Workbook
Name AcctPayableDays: 'SBUX Ratios'!$I$16
Name AcctRecDays: 'SBUX Ratios'!$I$14
Name AcctsPayable: 'SBUX Balance Sheet'!$U$10
Name AcctsReceivable: 'SBUX Balance Sheet'!$H$14
Name CFFFA: 'SBUX Cash Flow'!$I$42
Name CFFIA: 'SBUX Cash Flow'!$I$31
Name CFFO: 'SBUX Cash Flow'!$I$24
Name CMLTD: 'SBUX Balance Sheet'!$U$19
Name COGS: 'SBUX Income Statement'!$H$11
Name CurrentAssets: 'SBUX Balance Sheet'!$H$20
Name CurrLiabilities: 'SBUX Balance Sheet'!$U$20
Name DeprandAmort: 'SBUX Cash Flow'!$I$8
Name DilutedEPS: 'SBUX Income Statement'!$H$34
Name EBIT: 'SBUX Income Statement'!$H$21
Name EBITDA: 'SBUX Income Statement'!$H$22
Name EBT: 'SBUX Income Statement'!$H$27
Name FCF: 'SBUX Cash Flow'!$I$32
Name GrossProfit: 'SBUX Income Statement'!$H$13
Name IncomeTax: 'SBUX Income Statement'!$H$28
Name InterestExpense: 'SBUX Income Statement'!$H$26
Name Inventory: 'SBUX Balance Sheet'!$H$16
Name InventoryDays: 'SBUX Ratios'!$I$15
Name Leases: 'SBUX Ratios'!$T$26
Name LongTermDebt: 'SBUX Balance Sheet'!$U$21
Name NetIncome: 'SBUX Income Statement'!$H$31
Name Revenue: 'SBUX Income Statement'!$H$10
Name TotalAssets: 'SBUX Balance Sheet'!$H$35
Name TotalEquity: 'SBUX Balance Sheet'!$U$32
Name TotalLiabilities: 'SBUX Balance Sheet'!$U$26
Name TotLiabandEquity: 'SBUX Balance Sheet'!$U$35

Sheet SBUX Income Statement
B2: Starbucks Corpporation
B3: Consolidated Income Statement
B4: USD $ in thousands
B6: 12 months ended | C6: 9/29/24 | D6: 10/1/23 | E6: 10/02/22 | F6: 10/03/21 | G6: 9/27/20 | H6: 9/29/19 | I6: 9/30/18 | J6: 10/1/17 | K6: 10/2/16 | L6: 9/27/15 | M6: 9/28/14
B7: Company-operated stores | C7: 29765.9 | D7: 29462.3 | E7: 26576.1 | F7: 24607 | G7: 19164.6 | H7: 21544400 | I7: 19690300 | J7: 17650700 | K7: 16844100 | L7: 15197300 | M7: 12977900
B8: Licensed stores | C8: 4505.1 | D8: 4512.7 | E8: 3655.5 | F8: 2683.6 | G8: 2327.1 | H8: 2875000 | I8: 2652200 | J8: 2355000 | K8: 2154200 | L8: 1861900 | M8: 1588600
B9: Other | C9: 1905.2 | D9: 2000.6 | E9: 2018.7 | F9: 1770 | G9: 2026.3 | H9: 2089200 | I9: 2377000 | J9: 2381100 | K9: 2317600 | L9: 2103500 | M9: 1881300
B10: Net revenues | C10: =SUM(C7:C9) -> 36176.2 | D10: =SUM(D7:D9) -> 35975.6 | E10: =SUM(E7:E9) -> 32250.3 | F10: =SUM(F7:F9) -> 29060.6 | G10: =SUM(G7:G9) -> 23518 | H10: =SUM(H7:H9) -> 26508600 | I10: =SUM(I7:I9) -> 24719500 | J10: =SUM(J7:J9) -> 22386800 | ... M10: =SUM(M7:M9) -> 16447800
B11: Product and distribution costs | C11: 11180.6 | D11: 11409.1 | E11: 10317.4 | F11: 8738.7 | G11: 7694.9 | H11: -8526900 | I11: -10174500 | J11: -7065800 | K11: -8511100 | L11: -7787500 | M11: -6858800
B12: Store operating expenses | C12: 15286.5 | D12: 14720.3 | E12: 13561.8 | F12: 11930.9 | G12: 10764 | H12: -10493600 | I12: -7193200 | J12: -8486400 | K12: -6064300 | L12: -5411100 | M12: -4638200
B13: Gross profit | C13: =C10-C11-C12 -> 9709.1 | D13: =+D10-D11-D12 -> 9846.2 | E13: =+E10-E11-E12 -> 8371.1 | F13: =+F10-F11-F12 -> 8391 | G13: =+G10-G11-G12 -> 5059.1 | H13: =SUM(H10:H12) -> 7488100 | I13: =SUM(I10:I12) -> 7351800 | J13: =SUM(J10:J12) -> 6834600 | K13: =SUM(K10:K11) -> 12804800 | L13: =SUM(L10:L11) -> 11375200 | M13: =SUM(M10:M11) -> 9589000
B15: Other operating expenses | C15: 565.6 | D15: 539.4 | E15: 461.5 | F15: 359.5 | G15: 430.3 | H15: 371000 | I15: 539300 | J15: 518000 | K15: -545400 | L15: -522400 | M15: -457300 | O15: =+D15+D11+D12 -> 26668.8 | S15: =-G11+G12+G15+G16 -> 4930.7
B16: Depreciation and amortization expenses | C16: 1512.6 | D16: 1362.6 | E16: 1447.9 | F16: 1441.7 | G16: 1431.3 | H16: 1377300 | I16: 1247000 | J16: 1011400 | K16: -980800 | L16: -893900 | M16: -709600 | O16: =+D10-O15 -> 9306.8 | P16: G&A | Q16: =+I17+I18+I19-I20 -> 1682200
B17: General and administrative expenses | C17: 2523.3 | D17: 2441.3 | E17: 2032 | F17: 1932.6 | G17: 1679.6 | H17: 1824100 | I17: 1759000 | J17: 1408400 | K17: -1360600 | L17: -1196700 | M17: -991300 | O17: =+O16/D10 -> 0.25869756 | P17: Selling | Q17: =+I12+I15 -> -6653900
B18: Litigation (charge) credit and Restructuring Costs | C18: 0 | D18: 21.8 | E18: 46 | F18: 170.4 | G18: 278.7 | H18: 135800 | I18: 224400 | J18: 153500 | K18: – | L18: – | M18: 20200 | P18: Deprec | Q18: =+I16 -> 1247000
B19: Gain on sale of properties | C19: 0 | D19: 91.3 | G19: 0 | H19: 0 | I19: 0 | J19: 0 | K19: – | L19: – | M19: –
B20: Income from equity investees | C20: 301.2 | D20: 298.4 | E20: 234.1 | F20: 385.3 | G20: 322.5 | H20: 298000 | I20: 301200 | J20: 391400 | K20: 318200 | L20: 249900 | M20: 268300
B21: Operating income (loss) | C21: =SUM(C13,C19,C20)-SUM(C15,C16,C17) -> 5408.8 | D21: =+D13-D15-D16-D17-D18+D19+D20 -> 5870.8 | E21: =+E13-E15-E16-E17-E18-E19+E20 -> 4617.8 | F21: =+F13-F15-F16-F17-F18-F19+F20 -> 4872.1 | G21: =+G13-G15-G16-G17-G18-G19+G20 -> 1561.7 | H21: =+H13-H15-H16-H17-H18-H19+H20 -> 4077900 | I21: =+I13-I15-I16-I17-I18-I19+I20 -> 3883300 | J21: =+J13-J15-J16-J17-J18-J19+J20 -> 4134700 | K21: =SUM(K13:K20) -> 10236200 | L21: =SUM(L13:L20) -> 9012100 | M21: =SUM(M13:M20) -> 7719300
B22: EBITDA (without adjustments) | C22: =(C21+'SBUX Cash Flow'!D8+'SBUX Cash Flow'!D9) -> 7028.1 | D22: =(D21+'SBUX Cash Flow'!E8+'SBUX Cash Flow'!E9) -> 7242.1 | E22: =(E21+'SBUX Cash Flow'!F8+'SBUX Cash Flow'!F9) -> 6109.7 | F22: =(F21+'SBUX Cash Flow'!G8+'SBUX Cash Flow'!G9) -> 6384.9 | G22: =(G21+'SBUX Cash Flow'!H8+'SBUX Cash Flow'!H9) -> 3011.9 | H22: =(H21+'SBUX Cash Flow'!I8+'SBUX Cash Flow'!I9) -> 5493400 | I22: =(I21+'SBUX Cash Flow'!J8+'SBUX Cash Flow'!J9) -> 5173200 | J22: =(J21+'SBUX Cash Flow'!K8+'SBUX Cash Flow'!K9) -> 5078200 | ... M22: =(M21+'SBUX Cash Flow'!N8+'SBUX Cash Flow'!N9) -> 8467300
B23: Gain from joint venture and other | E23: 0 | F23: 0 | G23: 0 | H23: 0 | I23: 1376400 | J23: 0 | K23: – | L23: 390600 | M23: –
B24: Gain from divestiture | E24: 0 | F24: 864.5 | G24: 0 | H24: 622800 | I24: 499200 | J24: 93500 | K24: – | L24: -61100 | M24: –
B25: Interest income and other, net | C25: 122.8 | D25: 81.2 | E25: 97 | F25: 90.1 | G25: 39.7 | H25: 96500 | I25: 191400 | J25: 181800 | K25: 108000 | L25: 43000 | M25: 142700
B26: Interest expense | C26: -562 | D26: -550.1 | E26: -482.9 | F26: -469.8 | G26: -437 | H26: -331000 | I26: -170300 | J26: -92500 | K26: -81300 | L26: -70500 | M26: -64100
B27: Earnings (loss) before income taxes | C27: =SUM(C21:C26)-C22 -> 4969.6 | D27: =SUM(D21:D26)-D22 -> 5401.9 | E27: =SUM(E21:E26)-E22 -> 4231.9 | F27: =SUM(F21:F26)-F22 -> 5356.9 | G27: =SUM(G21:G26)-G22 -> 1164.4 | H27: =SUM(H21:H26)-EBITDA -> 4466200 | I27: =SUM(I21:I26) -> 10953200 | J27: =SUM(J21:J26) -> 9395700 | K27: =SUM(K21:K26) -> 21529100 | L27: =SUM(L21:L26) -> 19260200 | M27: =SUM(M21:M26) -> 16265200
B28: Income tax (expense) benefit | C28: 1207.3 | D28: 1277.2 | E28: 948.5 | F28: 1156.6 | G28: 239.7 | H28: 871600 | I28: 1262000 | J28: 1432600 | K28: -1379700 | L28: -1143700 | M28: -1092000
B29: Net earnings including noncontrolling interests | C29: =+C27-C28 -> 3762.3 | D29: =+D27-D28 -> 4124.7 | E29: =+E27-E28 -> 3283.4 | F29: =+F27-F28 -> 4200.3 | G29: =+G27-G28 -> 924.7 | H29: =+H27-H28 -> 3594600 | I29: =+I27-I28 -> 9691200 | J29: =+J27-J28 -> 7963100 | K29: =SUM(K27:K28) -> 20149400 | L29: =SUM(L27:L28) -> 18116500 | M29: =SUM(M27:M28) -> 15173200
B30: Earnings (loss) from noncontrolling interests | C30: 1.4 | D30: 0.2 | E30: 1.8 | F30: 1 | G30: -3.6 | H30: -4600 | I30: -300 | J30: 200 | K30: -1200 | L30: -1900 | M30: 400
B31: Net earnings attributable to Starbucks | C31: =C29-C30 -> 3760.9 | D31: =+D29-D30 -> 4124.5 | E31: =+E29-E30 -> 3281.6 | F31: =+F29-F30 -> 4199.3 | G31: =+G29-G30 -> 928.3 | H31: =+H29-H30 -> 3599200 | I31: =+I29-I30 -> 9691500 | J31: =+J29-J30 -> 7962900 | K31: =SUM(K29:K30) -> 20148200 | L31: =SUM(L29:L30) -> 18114600 | M31: =SUM(M29:M30) -> 15173600
B33: Earnings per share — basic | C33: 3.32 | D33: 3.6 | E33: 2.85 | F33: 3.57 | G33: 0.79 | H33: =+H31/H36 -> 2.947265 | I33: =+I31/I36 -> 7.0091126 | J33: =+J31/J36 -> 5.4935495 | K33: 1.91 | L33: 1.84 | M33: 1.37
B34: Earnings per share — diluted | C34: 3.31 | D34: 3.58 | E34: 2.83 | F34: 3.54 | G34: 0.79 | H34: =+H31/H37 -> 2.9185858 | I34: =+I31/I37 -> 6.9493045 | J34: =+J31/J37 -> 5.4484434 | K34: 1.9 | L34: 1.82 | M34: 1.35
B35: Weighted average shares outstanding:
B36: Basic | C36: 1133.8 | D36: 1146.8 | E36: 1153.3 | F36: 1177.6 | G36: 1172.8 | H36: 1221200 | I36: 1382700 | J36: 1449500 | K36: 1471.6 | L36: 1495.9 | M36: 1506.3
B37: Diluted | C37: 1137.3 | D37: 1151.3 | E37: 1158.5 | F37: 1185.5 | G37: 1181.8 | H37: 1233200 | I37: 1394600 | J37: 1461500 | K37: 1486.7 | L37: 1513.4 | M37: 1526.3
B40: Starbucks Corpporation
B41: Consolidated Income Statement
B42: USD $ in thousands
B44: 12 months ended | C44: =+C6 -> 9/29/24 | D44: 10/1/23 | E44: 10/02/22 | F44: 10/03/21 | G44: 9/27/20
B45: Company-operated stores
B46: Licensed stores
B47: Other
...

Sheet SBUX Balance Sheet
O1: B
B5: Starbucks Corporation
B6: Consolidated Statement of Financial Position
B7: USD $ in thousands
C9: =+'SBUX Income Statement'!C6 -> 9/29/24 | D9: =+'SBUX Income Statement'!D6 -> 10/1/23 | E9: 9/29/22 | F9: 9/30/21 | G9: 9/27/20 | H9: 9/29/19 | I9: 9/30/18 | J9: 10/1/17 | K9: 10/2/16 | L9: 9/27/15 | M9: 9/28/14 | P9: =+'SBUX Income Statement'!C6 -> 9/29/24 | Q9: =+'SBUX Income Statement'!D6 -> 10/1/23 | R9: 10/02/22 | S9: 10/03/21 | T9: 9/27/20 | U9: 9/29/19 | V9: 9/30/18 | W9: 10/1/17 | X9: 10/2/16 | Y9: 9/27/15 | Z9: 9/28/14
B10: Cash and cash equivalents | C10: 3286.2 | D10: 3551.5 | E10: 2818.4 | F10: 6455.7 | G10: 4350.9 | H10: 2686600 | I10: 8756300 | J10: 2462300 | K10: 2128800 | L10: 1530100 | M10: 1708400 | O10: Accounts payable | P10: 1595.5 | Q10: 1544.3 | R10: 1441.4 | S10: 1211.6 | T10: 997.9 | U10: 1189700 | V10: 1179300 | W10: 782500 | X10: 730600 | Y10: 684200 | Z10: 533700
B11: Short-term investments | C11: 257 | D11: 401.5 | E11: 364.5 | F11: 162.2 | G11: 281.2 | H11: 70500 | I11: 181500 | J11: 228600 | K11: 134400 | L11: 81300 | M11: 135400 | O11: Accrued compensation | P11: 786.6 | Q11: 828.3 | R11: 761.7 | S11: 772.3 | T11: 696 | U11: 664600 | V11: 656800 | X11: 510800 | Y11: 522300 | Z11: 437900
B12: Cash plus short-term investments | C12: =SUM(C10,C11) -> 3543.2 | D12: =+D10+D11 -> 3953 | E12: =+E10+E11 -> 3182.9 | F12: =+F10+F11 -> 6617.9 | G12: =+G10+G11 -> 4632.1 | H12: =+H10+H11 -> 2757100 | I12: =+I10+I11 -> 8937800 | J12: =+J10+J11 -> 2690900 | K12: =+K10+K11 -> 2263200 | L12: 1611400 | M12: 1843800 | O12: Accrued occupancy costs | X12: 137500 | Y12: 137200 | Z12: 119800
O13: Accrued taxes | T13: 98.2 | U13: 1291700 | V13: 102800 | X13: 368400 | Y13: 259000 | Z13: 272000
B14: Accounts receivable, net | C14: 1213.8 | D14: 1184.1 | E14: 1175.5 | F14: 940 | G14: 883.4 | H14: 879200 | I14: 693100 | J14: 870400 | K14: 768800 | L14: 719000 | M14: 631000 | O14: Accrued dividends payable | X14: 365100 | Y14: 297000 | Z14: 239800
O15: Accrued expenditures | X15: 617300 | Y15: =545200-5400 -> 539800 | Z15: 444900
B16: Inventories | C16: 1777.3 | D16: 1806.4 | E16: 2176.6 | F16: 1603.9 | G16: 1551.4 | H16: 1529400 | I16: 1400500 | J16: 1364000 | K16: 1378500 | L16: 1306400 | M16: 1090900 | O16: Accrued liabilities | P16: 2194.7 | Q16: 2145.1 | R16: 2137.1 | S16: 2321.2 | T16: 1160.7 | U16: 1753700 | V16: 1752500 | W16: 1934500 | X16: =SUM(X11:X15) -> 1999100 | Y16: =SUM(Y11:Y15) -> 1755300 | Z16: =SUM(Z11:Z15) -> 1514400
O17: C.P. of operating lease liab. | P17: 1463.1 | Q17: 1275.3 | R17: 1245.7 | S17: 1251.3 | T17: 1248.8 | U17: 0 | V17: 0 | W17: 215200 | X17: 246000 | Y17: 224800 | Z17: 196100
B18: Prepaids and other current assets | C18: 313.1 | D18: 359.9 | E18: 483.7 | F18: 594.6 | G18: 739.5 | H18: 488200 | I18: 1462800 | J18: 358100 | K18: 350000 | L18: 334200 | M18: 285600 | O18: Stored value card & Insurance | P18: 1781.2 | Q18: 1700.2 | R18: 1641.9 | S18: 1596.1 | T18: 1456.5 | U18: 1269000 | V18: 1642900 | W18: 1288500 | X18: 1171200 | Y18: 983800 | Z18: 794500
B19: Deferred income taxes, net | K19: 0 | M19: 317400 | O19: Short-Term Debt plus CPLTD | P19: 1248.9 | Q19: =33.5+1818.6 -> 1852.1 | R19: =175+1749 -> 1924 | S19: 998.9 | T19: =438.8+1249.9 -> 1688.7 | U19: 0 | V19: 349900 | W19: 0 | X19: 400000
B20: Current assets | C20: =SUM(C12,C16,C14,C18) -> 6847.4 | D20: =SUM(D12:D19) -> 7303.4 | E20: =SUM(E12:E19) -> 7018.7 | F20: =SUM(F12:F19) -> 9756.4 | G20: =SUM(G12:G19) -> 7806.4 | H20: =SUM(H12:H19) -> 5653900 | I20: =SUM(I12:I19) -> 12494200 | J20: =SUM(J12:J19) -> 5283400 | K20: =SUM(K12:K19) -> 4760500 | ... M20: =SUM(M12:M19) -> 4168700 | O20: Current liabilities | P20: =SUM(P10:P19) -> 9070 | Q20: =SUM(Q10:Q19) -> 9345.3 | R20: =SUM(R10:R19) -> 9151.8 | S20: =SUM(S10:S19) -> 8151.4 | T20: =SUM(T10:T19) -> 7346.8 | U20: =SUM(U10:U19) -> 6168700 | V20: =SUM(V10:V19) -> 5684200 | W20: =+W10+W16+W17+W18+W19 -> 4220700 | X20: =+X10+X16+X17+X18+X19 -> 4546900 | Y20: =+Y10+Y16+Y17+Y18+Y19 -> 3648100 | Z20: =+Z10+Z16+Z17+Z18+Z19 -> 3038700
B21: Long-term investments | C21: 276 | D21: 247.4 | E21: 279.1 | F21: 281.7 | G21: 206.1 | H21: 220000 | I21: 267700 | J21: 542300 | K21: 1141700 | L21: 312500 | M21: 318400 | O21: Long-term debt | P21: 14319.5 | Q21: 13547.6 | R21: 13119.9 | S21: 13616.9 | T21: 14659.6 | U21: 11167000 | V21: 9090200 | W21: 3932600 | X21: 3202200 | Y21: 2347500 | Z21: 2048300
B22: Equity method investments | C22: 463.9 | D22: 439.9 | E22: 311.2 | F22: 268.5 | G22: 478.7 | H22: 396000 | I22: 334700 | J22: 481600 | K22: 305700 | L22: 306400 | M22: 469300 | O22: Deferred Revenue | P22: 5963.6 | Q22: 6101.8 | R22: 6279.7 | S22: 6463 | T22: 6598.5 | U22: 6744400 | V22: 6775700 | W22: 4400 | Y22: 600900 | Z22: 392200
O23: Operating Lease Liability | P23: 8771.6 | Q23: 7924.8 | R23: 7515.2 | S23: 7738 | T23: 7661.7 | U23: 0 | V23: 0
B24: Cost method investments | J24: 0 | K24: 48800 | L24: 45600 | M24: 45600 | O24: Other long-term liabilities | P24: 656.2 | Q24: 513.8 | R24: 610.5 | S24: 737.8 | T24: 907.3 | U24: 1370500 | V24: 1430500 | W24: =755300-4400 -> 750900 | X24: 689700 | Y24: =+Y21+Y22 -> 2948400 | Z24: =+Z21+Z22 -> 2440500
B25: Equity and cost investments | C25: 463.9 | D25: =SUM(D22:D24) -> 439.9 | E25: =SUM(E22:E24) -> 311.2 | F25: =SUM(F22:F24) -> 268.5 | G25: =SUM(G22:G24) -> 478.7 | H25: =SUM(H22:H24) -> 396000 | I25: =SUM(I22:I24) -> 334700 | J25: =SUM(J22:J24) -> 481600 | K25: =+K22+K24 -> 354500 | L25: =+L22+L24 -> 352000 | M25: =+M22+M24 -> 514900 | O25: Noncurrent liabilities | P25: =SUM(P21:P24) -> 29710.9 | Q25: =+Q21+Q22+Q23+Q24 -> 28088 | R25: =+R21+R22+R23+R24 -> 27525.3 | S25: =+S21+S22+S23+S24 -> 28555.7 | T25: =+T21+T22+T23+T24 -> 29827.1 | U25: =+U21+U22+U24 -> 19281900 | V25: =+V21+V22+V24 -> 17296400 | W25: =+W21+W22+W24 -> 4687900 | X25: =+X21+X24 -> 3891900 | Y25: =+Y20+Y24 -> 6596500 | Z25: =+Z20+Z24 -> 5479200
B26: Property, plant and equipment, net | C26: 8665.5 | D26: 7387.1 | E26: 6560.5 | F26: 6369.5 | G26: 6241.4 | H26: 6431700 | I26: 5929100 | J26: 4919500 | K26: 4533800 | L26: 4088300 | M26: 3519000 | O26: Total liabilities | P26: =P20+P25 -> 38780.9 | Q26: =+Q20+Q25 -> 37433.3 | R26: =+R20+R25 -> 36677.1 | S26: =+S20+S25 -> 36707.1 | T26: =+T20+T25 -> 37173.9 | U26: =+U20+U25 -> 25450600 | V26: =+V20+V25 -> 22980600 | W26: =+W20+W25 -> 8908600 | X26: =+X20+X25 -> 8438800 | Y26: 1500 | Z26: 700
B27: Deferred income taxes, net | C27: 1766.7 | D27: 1769.8 | E27: 1799.7 | F27: 1874.8 | G27: 1789.9 | H27: 1765800 | I27: 134700 | J27: 795400 | K27: 885400 | L27: 1180800 | M27: 903300 | O27: Common stock; $0.001 par | P27: 1.1 | Q27: 1.1 | R27: 1.1 | S27: 1.2 | T27: 1.2 | U27: 1200 | V27: 1300 | W27: 1400 | X27: 1500 | Y27: 41100 | Z27: 39400
B28: Other long-term assets | C28: 617 | D28: 546.5 | E28: 554.2 | F28: 578.5 | G28: 568.6 | H28: 479600 | I28: 412200 | J28: 362800 | K28: 417700 | L28: 415900 | M28: 198900 | O28: Additional paid-in capital | P28: 322.6 | Q28: 38.1 | R28: 205.3 | S28: 846.1 | T28: 373.9 | U28: 41100 | V28: 41100 | W28: 41100 | X28: 41100 | Y28: 5974800 | Z28: 5206600
B29: Other intangible assets | C29: 100.9 | D29: 120.5 | E29: 155.9 | F29: 349.9 | G29: 552.1 | H29: 781800 | I29: 1042200 | J29: 441400 | K29: 516300 | L29: 520400 | M29: 273500 | O29: Retained earnings/(deficit) | P29: -7343.8 | Q29: -7255.8 | R29: -8449.8 | S29: -6315.7 | T29: -7815.6 | U29: -5771200 | V29: 1457400 | W29: 5563200 | X29: 5949800 | Y29: -199400 | Z29: 25300
B30: Goodwill | C30: 3315.7 | D30: 3218.3 | E30: 3283.5 | F30: 3677.3 | G30: 3597.2 | H30: 3490800 | I30: 3541600 | J30: 1539200 | K30: 1719600 | L30: 1575400 | M30: 856200 | O30: Accum. other compr. Inc. | P30: -428.8 | Q30: -778.2 | R30: -463.2 | S30: 147.2 | T30: -364.6 | U30: -503300 | V30: -330300 | W30: -155600 | X30: -108400
B31: Operating Lease, right-of-use asset | C31: 9286.2 | D31: 8412.6 | E31: 8015.6 | F31: 8236 | G31: 8134.1 | H31: 0 | I31: 0
B32: Noncurrent assets | C32: =SUM(C21:C31) -> 24955.8 | D32: =SUM(D25:D31)+D21 -> 22142.1 | E32: =SUM(E25:E31)+E21 -> 20959.7 | F32: =SUM(F25:F31)+F21 -> 21636.2 | G32: =SUM(G25:G31)+G21 -> 21568.1 | H32: =+H21+H25+H26+H27+H28+H29+H30 -> 13565700 | I32: =+I21+I25+I26+I27+I28+I29+I30 -> 11662200 | J32: =+J21+J25+J26+J27+J28+J29+J30 -> 9082200 | K32: =+K21+K25+K26+K27+K28+K29+K30 -> 9569000 | L32: =+L21+L25+L26+L27+L28+L29+L30 -> 8445300 | M32: =+M21+M25+M26+M27+M28+M29+M30 -> 6584200 | O32: Total equity | P32: -7448.9 | Q32: =SUM(Q27:Q30) -> -7994.8 | R32: =SUM(R27:R30) -> -8706.6 | S32: =SUM(S27:S30) -> -5321.2 | T32: =SUM(T27:T30) -> -7805.1 | U32: =SUM(U27:U30) -> -6232200 | V32: =SUM(V27:V30) -> 1169500 | W32: =SUM(W27:W30) -> 5450100 | X32: =SUM(X27:X30) -> 5884000 | Y32: =SUM(Y26:Y29) -> 5818000 | Z32: =SUM(Z26:Z29) -> 5272000
O33: Noncontrolling interests | P33: 7.3 | Q33: 7 | R33: 7.9 | S33: 6.7 | T33: 5.7 | U33: 1200 | V33: 6300 | W33: 6900 | X33: 6700 | Y33: 1800 | Z33: 1700
O34: Total Starbucks Shareholders'Equty | P34: -7441.6 | Q34: =+Q32-Q33 -> -8001.8 | R34: =+R32-R33 -> -8714.5 | S34: =+S32-S33 -> -5327.9 | T34: =+T32-T33 -> -7810.8 | U34: =+U32-U33 -> -6233400 | V34: =+V32-V33 -> 1163200 | W34: =+W32-W33 -> 5443200 | X34: =+X32-X33 -> 5877300 | ... Z34: =+Z32-Z33 -> 5270300
B35: Total assets | C35: =C20+C32 -> 31803.2 | D35: =+D20+D32 -> 29445.5 | E35: =+E20+E32 -> 27978.4 | F35: =+F20+F32 -> 31392.6 | G35: =+G20+G32 -> 29374.5 | H35: =+H20+H32 -> 19219600 | I35: =+I20+I32 -> 24156400 | J35: =+J20+J32 -> 14365600 | K35: =+K20+K32 -> 14329500 | ... M35: =+M20+M32 -> 10752900 | O35: Total Liabilities and Equity | P35: =P34+P26 -> 31339.3 | Q35: =+Q26+Q32+Q33 -> 29445.5 | R35: =+R26+R32+R33 -> 27978.4 | S35: =+S26+S32+S33 -> 31392.6 | T35: =+T26+T32+T33 -> 29374.5 | U35: =+U26+U32+U33 -> 19219600 | V35: =+V26+V32+V33 -> 24156400 | W35: =+W26+W32+W33 -> 14365600 | X35: =+X26+X32+X33 -> 14329500 | Y35: =+Y25+Y32+Y33 -> 12416300 | Z35: =+Z25+Z32+Z33 -> 10752900
AC46: =+AC45+AC44 -> 0

Sheet SBUX Cash Flow
C2: Starbucks Corporation
C3: Consolidated Statement of Cash Flows
C4: USD $ in thousands
C6: 12 months ended | D6: =+'SBUX Income Statement'!C6 -> 9/29/24 | E6: =+'SBUX Income Statement'!D6 -> 10/1/23 | F6: 10/02/22 | G6: 10/03/21 | H6: 9/27/20 | I6: 9/29/19 | J6: 9/29/19 | K6: 10/1/17 | L6: 10/2/16 | M6: 9/27/15 | N6: 9/28/14
C7: Net earnings including noncontrolling interests | D7: 3762.3 | E7: 4124.7 | F7: 3283.4 | G7: 4200.3 | H7: 924.7 | I7: 3594600 | J7: 4518000 | K7: 2884900 | L7: 2819000 | M7: 2759000 | N7: 2068000
C8: Depreciation and amortization | D8: 1592.4 | E8: 1450.3 | F8: 1529.4 | G8: 1524.1 | H8: 1503.2 | I8: 1449300 | J8: 1305900 | K8: 1067100 | L8: 1030000 | M8: 934000 | N8: 748000 | P8: Total Working Capital
C9: Equity Method Income Net of Receipts | D9: =-306.4+333.3 -> 26.9 | E9: =-301.8+222.8 -> -79 | F9: =-268.7+231.2 -> -37.5 | G9: =-347.3+336 -> -11.3 | H9: =-280.7+227.7 -> -53 | I9: =-250600+216800 -> -33800 | J9: =-242800+226800 -> -16000 | K9: =-310200+186600 -> -123600
C10: Gain on sale of properties | D10: 0 | E10: -91.3 | F10: 0 | G10: -864.5 | H10: 0 | I10: -622800 | J10: -499200 | K10: -93500 | N10: -70000 | P10: 9/30/18 | Q10: 10/1/17
C11: Gain from Acquisition of joint venture | F11: 0 | G11: 0 | I11: 0 | J11: -1376400 | K11: 0 | P11: =SUM(J10:J23) -> 6129900 | Q11: =SUM(K10:K23) -> 423400
C12: Deferred income taxes, net | D12: -13.8 | E12: -59.4 | F12: -37.8 | G12: -146.2 | H12: -25.8 | I12: -1495400 | J12: 714900 | K12: 95100 | L12: 266000 | M12: 21000 | N12: 10000
C13: Stock-based compensation | D13: 308.3 | E13: 302.7 | F13: 271.5 | G13: 319.1 | H13: 248.6 | I13: 308000 | J13: 250300 | K13: 176000 | L13: 218000 | M13: 210000 | N13: 183000
C14: Non-cash lease cost | D14: 1314.9 | E14: 1365.9 | F14: 1497.7 | G14: 1248.6 | H14: 1197.6
C15: Other Non-Cash Gain/Loss | D15: =121.5+31.9 -> 153.4 | E15: =101.4+26.8 -> 128.2 | F15: =91.4-67.8 -> 23.6 | G15: =226.2-6 -> 220.2 | H15: =454.4+24.5 -> 478.9 | I15: =187900+10500 -> 198400 | J15: =37600+89000 -> 126600 | K15: =68900+87200 -> 156100
C16: Accounts receivable | D16: 18.4 | E16: -4.1 | F16: -326.1 | G16: -43 | H16: -2.7 | I16: -197700 | J16: 131000 | K16: -96800 | L16: -56000 | M16: -83000 | N16: -80000
C17: Inventories | D17: 42.8 | E17: 366.4 | F17: -641 | G17: -49.8 | H17: -10.9 | I17: -173000 | J17: -41200 | K17: 14000 | L17: -68000 | M17: -208000 | N17: 14000
C18: Prepaid Expenses and other | E18: 0 | H18: -317.5 | I18: 922000 | J18: -839500 | K18: -20000
C19: Accounts payable | D19: 28 | E19: 100.1 | F19: 345.5 | G19: 189.9 | H19: -210.8 | I19: 31900 | J19: 391600 | K19: 46400 | L19: 48000 | M19: 138000 | N19: 60000
C20: Income Taxes Payable | D20: -61.9 | E20: 52.5 | F20: -149.6 | G20: 286.1 | H20: -1214.6 | I20: 1237100 | J20: 146000 | K20: -91900 | M20: 124000 | N20: -2660000
C21: Stored value card liability (Deferred Revenue) | D21: -72.2 | E21: -110.8 | F21: -75.8 | G21: -6.1 | H21: 31 | I21: -30500 | J21: 7109400 | K21: 130800 | L21: 429000 | M21: 170000 | N21: 141000 | R21: =6008.7-E24 -> 0
C22: Operating Lease Liability | D22: -1294.9 | E22: -1443.8 | F22: -1625.6 | G22: -1488.1 | H22: -1231.4
C23: Other operating assets and liabilities | D23: 291 | E23: -93.7 | F23: 339.6 | G23: 609.8 | H23: 280.5 | I23: -141100 | J23: 16400 | K23: 107200 | L23: -111000 | M23: -316000 | N23: 193000
C24: Cash Flow From Operations | D24: =D7+D8+D9+D12+D13+D14+D15+D16+D17+D19+D20+D21+D22+D23 -> 6095.6 | E24: =SUM(E7:E23) -> 6008.7 | F24: =SUM(F7:F23) -> 4397.3 | G24: =SUM(G7:G23) -> 5989.1 | H24: =SUM(H7:H23) -> 1597.8 | I24: =SUM(I7:I23) -> 5047000 | J24: =SUM(J7:J23) -> 11937800 | K24: =SUM(K7:K23) -> 4251800 | L24: =SUM(L7:L23) -> 4575000 | ... N24: =SUM(N7:N23) -> 607000 | R24: =+J24-11937800 -> 0
C26: Purchase of investments | D26: -627.5 | E26: -610.5 | F26: -377.9 | G26: -432 | H26: -443.9 | I26: -190400 | J26: -191900 | K26: -674400 | L26: -1585700 | M26: -567000 | N26: -1652000
C27: Sales of investments | D27: 10.3 | E27: 2.5 | F27: 72.6 | G27: 143.2 | H27: 186.7 | I27: 298300 | J27: 459000 | K27: 1054500 | L27: 680700 | M27: 628000 | N27: 2015000
C28: Acquisitions, net of cash acquired | F28: 59.3 | G28: 1175 | H28: 0 | I28: 0 | J28: -1311300 | K28: 0 | M28: -284000
C29: Additions to property, plant and equipment | D29: -2777.5 | E29: -2333.6 | F29: -1841.3 | G29: -1470 | H29: -1483.6 | I29: -1806600 | J29: -1976400 | K29: -1519400 | L29: =-1440300+69600+27900 -> -1342800 | M29: -1304000 | N29: -1161000
C30: Other | D30: =768-72.7 -> 695.3 | E30: =616.9+110-56.1 -> 670.8 | F30: =67.3-126.3 -> -59 | G30: =345.5-81.2 -> 264.3 | H30: =-44.4+73.7 -> 29.3 | I30: =684300-56200+59800 -> 687900 | J30: =608200+5600+45300 -> 659100 | K30: =149600+85400+54300 -> 289300 | L30: 24900 | M30: 7000 | N30: -19000
C31: Net cash used by investing activities | D31: =D26+D27+D29+D30 -> -2699.4 | E31: =SUM(E26:E30) -> -2270.8 | F31: =SUM(F26:F30) -> -2146.3 | G31: =SUM(G26:G30) -> -319.5 | H31: =SUM(H26:H30) -> -1711.5 | I31: =SUM(I26:I30) -> -1010800 | J31: =SUM(J26:J30) -> -2361500 | K31: =SUM(K26:K30) -> -850000 | L31: =SUM(L26:L30) -> -2222900 | ... N31: =SUM(N26:N30) -> -817000
C32: FREE CASH FLOW | D32: =D24+D31 -> 3396.2 | E32: =+E24+E31 -> 3737.9 | F32: =+F24+F31 -> 2251 | G32: =+G24+G31 -> 5669.6 | H32: =+H24+H31 -> -113.7 | I32: =+I24+I31 -> 4036200 | J32: =+J24+J31 -> 9576300 | K32: =+K24+K31 -> 3401800 | L32: =+L24+L31 -> 2352100 | ... N32: =+N24+N31 -> -210000
C33: Net increase (decrease) in short term debt | D33: =123.8-157.5 -> -33.7 | E33: =-175+114.6-78.8 -> -139.2 | F33: =175+36.6-36.6 -> 175 | G33: =-296.5+215.1-349.8 -> -431.2 | H33: =1406.6-967.7 -> 438.9
C34: Proceeds from issuance of long-term debt | D34: 1995.3 | E34: 1497.8 | F34: 1498.1 | G34: 0 | H34: 4727.6 | I34: 1996000 | J34: 5584100 | K34: 750200 | L34: 1254000 | M34: 848000 | N34: 748000
C35: Repayments of long-term debt | D35: -1825.1 | E35: -1000 | F35: -1000 | G35: -1250 | H35: 0 | I35: -350000 | J35: 0 | K35: -400000 | M35: -610000
C36: Proceeds from issuance of common stock | D36: 108 | E36: 167.4 | F36: 101.6 | G36: 246.2 | H36: 298.8 | I36: 409800 | J36: 153900 | K36: 150800 | L36: 161000 | M36: 192000 | N36: 140000
C37: Excess tax benefit on share-based awards | L37: 123000 | M37: 132000 | N37: 114000
C38: Cash dividends paid | D38: -2585 | E38: -2431.8 | F38: -2263.3 | G38: -2119 | H38: -1923.5 | I38: -1761300 | J38: -1743400 | K38: -1450400 | L38: -1178000 | M38: -929000 | N38: -783000
C39: Repurchase of common stock | D39: -1266.7 | E39: -984.4 | F39: -4013 | G39: 0 | H39: -1698.9 | I39: -10222300 | J39: -7133500 | K39: -2042500 | L39: -1996000 | M39: -1436000 | N39: -759000
C40: Minimum tax withholdings on share-based awards | D40: -100.4 | E40: -89.3 | F40: -127.2 | G40: -97 | H40: -91.9 | I40: -111600 | J40: -62700 | K40: -82800
C41: Other | D41: -10.6 | E41: -11.1 | F41: -9.2 | G41: 0 | H41: -37.7 | I41: -17500 | J41: -41200 | K41: -4400 | L41: -114000 | M41: -454000 | N41: -84000
C42: Net cash used by financing activities | D42: =SUM(D33,D34,D35,D36,D38,D39,D40,D41) -> -3718.2 | E42: =SUM(E33:E41) -> -2990.6 | F42: =SUM(F33:F41) -> -5638 | G42: =SUM(G33:G41) -> -3651 | H42: =SUM(H33:H41) -> 1713.3 | I42: =SUM(I34:I41) -> -10056900 | J42: =SUM(J34:J41) -> -3242800 | K42: =SUM(K34:K41) -> -3079100 | L42: =SUM(L34:L41) -> -1750000 | M42: =SUM(M34:M41) -> -2257000 | N42: =SUM(N34:N41) -> -624000
C43: Effect of exchange rate changes on cash and cash equivalents | D43: 56.5 | E43: -14.2 | F43: -250.3 | G43: 86.2 | H43: 64.7 | I43: -49000 | J43: -39500 | K43: 10800 | L43: -3400 | M43: -151000 | N43: -34000
...

Sheet SBUX Ratios
B3: Starbucks Corporation
B4: Ratio Analysis
D6: =+'SBUX Income Statement'!C6 -> 9/29/24 | E6: =+'SBUX Income Statement'!D6 -> 10/1/23 | F6: 10/02/22 | G6: 10/03/21 | H6: 9/27/20 | I6: 9/29/19 | J6: 9/30/18 | K6: 10/1/17 | L6: 10/2/16 | M6: 9/27/15 | N6: 9/28/14
B7: PROFITABILITY
B9: Gross Profit Margin | C9: 25.87 | D9: ='SBUX Income Statement'!C13/'SBUX Income Statement'!C10 -> 0.26838363 | E9: ='SBUX Income Statement'!D13/'SBUX Income Statement'!D10 -> 0.27369106 | F9: ='SBUX Income Statement'!E13/'SBUX Income Statement'!E10 -> 0.25956658 | G9: ='SBUX Income Statement'!F13/'SBUX Income Statement'!F10 -> 0.28874146 | L9: =+'SBUX Income Statement'!K13/'SBUX Income Statement'!K10 -> 0.6007159 | M9: =+'SBUX Income Statement'!L13/'SBUX Income Statement'!L10 -> 0.59361155 | N9: =+'SBUX Income Statement'!M13/'SBUX Income Statement'!M10 -> 0.5829959
B10: Operating Profit Margin | D10: ='SBUX Income Statement'!C27/'SBUX Income Statement'!C10 -> 0.13737208 | E10: ='SBUX Income Statement'!D27/'SBUX Income Statement'!D10 -> 0.15015455 | F10: ='SBUX Income Statement'!E27/'SBUX Income Statement'!E10 -> 0.13122048 | G10: ='SBUX Income Statement'!F27/'SBUX Income Statement'!F10 -> 0.18433549 | L10: =+'SBUX Income Statement'!K21/'SBUX Income Statement'!K10 -> 0.4802143 | M10: =+'SBUX Income Statement'!L21/'SBUX Income Statement'!L10 -> 0.47029385 | N10: =+'SBUX Income Statement'!M21/'SBUX Income Statement'!M10 -> 0.46932113
B11: Net Profit Margin | D11: ='SBUX Income Statement'!C31/'SBUX Income Statement'!C10 -> 0.10396061 | E11: ='SBUX Income Statement'!D31/'SBUX Income Statement'!D10 -> 0.11464715 | F11: ='SBUX Income Statement'!E31/'SBUX Income Statement'!E10 -> 0.10175409 | G11: ='SBUX Income Statement'!F31/'SBUX Income Statement'!F10 -> 0.14450149 | L11: =+'SBUX Income Statement'!K31/'SBUX Income Statement'!K10 -> 0.9452193 | M11: =+'SBUX Income Statement'!L31/'SBUX Income Statement'!L10 -> 0.9453052 | N11: =+'SBUX Income Statement'!M31/'SBUX Income Statement'!M10 -> 0.92253067
B13: EFFICIENCY
B14: A/R DOH (not ave.) | D14: =('SBUX Balance Sheet'!C14/'SBUX Income Statement'!C10)*365 -> 12.246643 | E14: =('SBUX Balance Sheet'!D14/'SBUX Income Statement'!D10)*365 -> 12.013601 | F14: =('SBUX Balance Sheet'!E14/'SBUX Income Statement'!E10)*365 -> 13.303985 | G14: =('SBUX Balance Sheet'!F14/'SBUX Income Statement'!F10)*365 -> 11.806363
B15: Inventory DOH (not ave.) | D15: =('SBUX Balance Sheet'!C16/'SBUX Income Statement'!C11)*365 -> 58.021439 | E15: =('SBUX Balance Sheet'!D16/'SBUX Income Statement'!D11)*365 -> 57.79036 | F15: =('SBUX Balance Sheet'!E16/'SBUX Income Statement'!E11)*365 -> 77.001861 | G15: =('SBUX Balance Sheet'!F16/'SBUX Income Statement'!F11)*365 -> 66.992058
B16: A/P DOH (not ave.) | D16: =('SBUX Balance Sheet'!P10/'SBUX Income Statement'!C11)*365 -> 52.086426 | E16: =('SBUX Balance Sheet'!Q10/'SBUX Income Statement'!D11)*365 -> 49.405255 | F16: =('SBUX Balance Sheet'!R10/'SBUX Income Statement'!E11)*365 -> 50.992595 | G16: =('SBUX Balance Sheet'!S10/'SBUX Income Statement'!F11)*365 -> 50.606383
B17: Total Asset Turnover (not ave.) | D17: ='SBUX Income Statement'!C10/'SBUX Balance Sheet'!C35 -> 1.1375019 | E17: ='SBUX Income Statement'!D10/'SBUX Balance Sheet'!D35 -> 1.221769 | F17: ='SBUX Income Statement'!E10/'SBUX Balance Sheet'!E35 -> 1.1526856 | G17: ='SBUX Income Statement'!F10/'SBUX Balance Sheet'!F35 -> 0.92571498
B18: Fixed Asset Turnover (not ave.) | D18: ='SBUX Income Statement'!C10/'SBUX Balance Sheet'!C26 -> 4.1747389 | E18: ='SBUX Income Statement'!D10/'SBUX Balance Sheet'!D26 -> 4.8700573 | F18: ='SBUX Income Statement'!E10/'SBUX Balance Sheet'!E26 -> 4.9158296 | G18: ='SBUX Income Statement'!F10/'SBUX Balance Sheet'!F26 -> 4.5624617
B20: LEVERAGE
B21: Debt/Equity | D21: ='SBUX Balance Sheet'!P26/'SBUX Balance Sheet'!P32 -> -5.2062586 | E21: ='SBUX Balance Sheet'!Q26/'SBUX Balance Sheet'!Q32 -> -4.6822059 | F21: ='SBUX Balance Sheet'!R26/'SBUX Balance Sheet'!R32 -> -4.2125629 | G21: ='SBUX Balance Sheet'!S26/'SBUX Balance Sheet'!S32 -> -6.8982748 | L21: =+(('SBUX Balance Sheet'!X21+'SBUX Balance Sheet'!X19)/('SBUX Balance Sheet'!X32)) -> 0.61220258 | M21: =+(('SBUX Balance Sheet'!Y21+'SBUX Balance Sheet'!Y19)/('SBUX Balance Sheet'!Y32)) -> 0.40348917 | N21: =+(('SBUX Balance Sheet'!Z21+'SBUX Balance Sheet'!Z19)/('SBUX Balance Sheet'!Z32)) -> 0.38852428
B22: LTD/Total Capital | D22: ='SBUX Balance Sheet'!P21/'SBUX Balance Sheet'!P35 -> 0.45691831 | E22: ='SBUX Balance Sheet'!Q21/'SBUX Balance Sheet'!Q35 -> 0.46009068 | F22: ='SBUX Balance Sheet'!R21/'SBUX Balance Sheet'!R35 -> 0.4689296 | G22: ='SBUX Balance Sheet'!S21/'SBUX Balance Sheet'!S35 -> 0.43376146 | L22: =+('SBUX Balance Sheet'!X21/('SBUX Balance Sheet'!X21+'SBUX Balance Sheet'!X32)) -> 0.35242456 | M22: =+('SBUX Balance Sheet'!Y21/('SBUX Balance Sheet'!Y21+'SBUX Balance Sheet'!Y32)) -> 0.28749005 | N22: =+('SBUX Balance Sheet'!Z21/('SBUX Balance Sheet'!Z21+'SBUX Balance Sheet'!Z32)) -> 0.27981094
B23: Debt/Total Capital | D23: ='SBUX Balance Sheet'!P26/'SBUX Balance Sheet'!P35 -> 1.2374527 | E23: ='SBUX Balance Sheet'!Q26/'SBUX Balance Sheet'!Q35 -> 1.271274 | F23: ='SBUX Balance Sheet'!R26/'SBUX Balance Sheet'!R35 -> 1.3109077 | G23: ='SBUX Balance Sheet'!S26/'SBUX Balance Sheet'!S35 -> 1.1692915 | L23: =+('SBUX Balance Sheet'!X19+'SBUX Balance Sheet'!X21)/('SBUX Balance Sheet'!X19+'SBUX Balance Sheet'!X21+'SBUX Balance Sheet'!X32) -> 0.37973056 | M23: =+('SBUX Balance Sheet'!Y19+'SBUX Balance Sheet'!Y21)/('SBUX Balance Sheet'!Y19+'SBUX Balance Sheet'!Y21+'SBUX Balance Sheet'!Y32) -> 0.28749005 | N23: =+('SBUX Balance Sheet'!Z19+'SBUX Balance Sheet'!Z21)/('SBUX Balance Sheet'!Z19+'SBUX Balance Sheet'!Z21+'SBUX Balance Sheet'!Z32) -> 0.27981094
B24: Debt/EBITDA (not ave.) | D24: ='SBUX Balance Sheet'!P21/('SBUX Income Statement'!C22+'SBUX Income Statement'!C16) -> 1.676619 | E24: ='SBUX Balance Sheet'!Q21/('SBUX Income Statement'!D22+'SBUX Income Statement'!D16) -> 1.5744419 | F24: ='SBUX Balance Sheet'!R21/('SBUX Income Statement'!E22+'SBUX Income Statement'!E16) -> 1.7359876 | G24: ='SBUX Balance Sheet'!S21/('SBUX Income Statement'!F22+'SBUX Income Statement'!F16) -> 1.7398232 | L24: =+('SBUX Balance Sheet'!X19+'SBUX Balance Sheet'!X21)/('SBUX Income Statement'!K22) -> 0.31973514 | M24: =+('SBUX Balance Sheet'!Y19+'SBUX Balance Sheet'!Y21)/('SBUX Income Statement'!L22) -> 0.23602216 | N24: =+('SBUX Balance Sheet'!Z19+'SBUX Balance Sheet'!Z21)/('SBUX Income Statement'!M22) -> 0.2419071 | U24: Operating Lease Expense
B25: Times Interest Earned | D25: ='SBUX Income Statement'!C27/-('SBUX Income Statement'!C26) -> 8.8427046 | E25: ='SBUX Income Statement'!D27/-('SBUX Income Statement'!D26) -> 9.8198509 | F25: ='SBUX Income Statement'!E27/-('SBUX Income Statement'!E26) -> 8.7635121 | G25: ='SBUX Income Statement'!F27/-('SBUX Income Statement'!F26) -> 11.402512 | L25: =+('SBUX Income Statement'!K21/'SBUX Income Statement'!K26)*-1 -> 125.90652 | M25: =+('SBUX Income Statement'!L21/'SBUX Income Statement'!L26)*-1 -> 127.83121 | N25: =+('SBUX Income Statement'!M21/'SBUX Income Statement'!M26)*-1 -> 120.4259 | O25: 2024 | P25: 2023 | Q25: 2022 | R25: 2021 | S25: 2020 | T25: 2019 | U25: 2018 | V25: 2017 | W25: 2016 | X25: 2014
B26: Fixed Charge Coverage | D26: =('SBUX Income Statement'!C22+'SBUX Income Statement'!C12)/('SBUX Income Statement'!C26+'SBUX Income Statement'!C12) -> 1.5154742 | E26: =('SBUX Income Statement'!D22+'SBUX Income Statement'!D12)/('SBUX Income Statement'!D26+'SBUX Income Statement'!D12) -> 1.5499005 | F26: =('SBUX Income Statement'!E22+'SBUX Income Statement'!E12)/('SBUX Income Statement'!E26+'SBUX Income Statement'!E12) -> 1.5040638 | G26: =('SBUX Income Statement'!F22+'SBUX Income Statement'!F12)/('SBUX Income Statement'!F26+'SBUX Income Statement'!F12) -> 1.598084 | L26: =+('SBUX Income Statement'!K21+W26)/('SBUX Income Statement'!K26-W26)*-1 -> 8.7845151 | M26: =+('SBUX Income Statement'!L21+#REF!)/('SBUX Income Statement'!L26-#REF!)*-1 -> #REF! | N26: =+('SBUX Income Statement'!M21+X26)/('SBUX Income Statement'!M26-X26)*-1 -> 8.372821 | P26: 1657.2 | Q26: 1647.3 | R26: 1707.1 | S26: 1463.3 | T26: 1666000 | U26: 1625200 | V26: 1329200 | W26: 1223200 | X26: 974200
B28: Liquidity
B29: Current Ratio | D29: ='SBUX Balance Sheet'!C20/'SBUX Balance Sheet'!P20 -> 0.75495039 | E29: ='SBUX Balance Sheet'!D20/'SBUX Balance Sheet'!Q20 -> 0.78150514 | F29: ='SBUX Balance Sheet'!E20/'SBUX Balance Sheet'!R20 -> 0.76692017 | G29: ='SBUX Balance Sheet'!F20/'SBUX Balance Sheet'!S20 -> 1.1968987 | H29: =+'SBUX Balance Sheet'!G20/'SBUX Balance Sheet'!T20 -> 1.0625578 | I29: =+'SBUX Balance Sheet'!H20/'SBUX Balance Sheet'!U20 -> 0.91654644 | J29: =+'SBUX Balance Sheet'!I20/'SBUX Balance Sheet'!V20 -> 2.1980578 | K29: =+'SBUX Balance Sheet'!J20/'SBUX Balance Sheet'!W20 -> 1.2517829 | L29: =+'SBUX Balance Sheet'!K20/'SBUX Balance Sheet'!X20 -> 1.0469771 | M29: =+'SBUX Balance Sheet'!L20/'SBUX Balance Sheet'!Y20 -> 1.0885118 | N29: =+'SBUX Balance Sheet'!M20/'SBUX Balance Sheet'!Z20 -> 1.3718695
B30: Quick Ratio | D30: =('SBUX Balance Sheet'!C20-'SBUX Balance Sheet'!C16)/'SBUX Balance Sheet'!P20 -> 0.55899669 | E30: =('SBUX Balance Sheet'!D20-'SBUX Balance Sheet'!D16)/'SBUX Balance Sheet'!Q20 -> 0.58821012 | F30: =('SBUX Balance Sheet'!E20-'SBUX Balance Sheet'!E16)/'SBUX Balance Sheet'!R20 -> 0.52908717 | G30: =('SBUX Balance Sheet'!F20-'SBUX Balance Sheet'!F16)/'SBUX Balance Sheet'!S20 -> 1.0001349 | H30: =+('SBUX Balance Sheet'!G20-'SBUX Balance Sheet'!G16)/'SBUX Balance Sheet'!T20 -> 0.85139108 | I30: =+('SBUX Balance Sheet'!H20-'SBUX Balance Sheet'!H16)/'SBUX Balance Sheet'!U20 -> 0.66861737 | J30: =+('SBUX Balance Sheet'!I20-'SBUX Balance Sheet'!I16)/'SBUX Balance Sheet'!V20 -> 1.9516731 | K30: =+('SBUX Balance Sheet'!J20-'SBUX Balance Sheet'!J16)/'SBUX Balance Sheet'!W20 -> 0.92861374 | L30: =+('SBUX Balance Sheet'!K20-'SBUX Balance Sheet'!K16)/'SBUX Balance Sheet'!X20 -> 0.74380347 | M30: =+('SBUX Balance Sheet'!L20-'SBUX Balance Sheet'!L16)/'SBUX Balance Sheet'!Y20 -> 0.73040761 | N30: =+('SBUX Balance Sheet'!M20-'SBUX Balance Sheet'!M16)/'SBUX Balance Sheet'!Z20 -> 1.0128673
B31: Cash Conversion Cycle | D31: =(D15+D14)-D16 -> 18.181655 | E31: =(E15+E14)-E16 -> 20.398706 | F31: =(F15+F14)-F16 -> 39.313251 | G31: =(G15+G14)-G16 -> 28.192038 | H31: =+H14+H15-H16 -> 0 | I31: =+I14+I15-I16 -> 0 | J31: =+J14+J15-J16 -> 0 | K31: =+K14+K15-K16 -> 0 | L31: =+L14+L15-L16 -> 0 | M31: =+M14+M15-M16 -> 0 | N31: =+N14+N15-N16 -> 0
B33: Returns
B34: Return on Equity (not ave.) | D34: ='SBUX Income Statement'!C31/'SBUX Balance Sheet'!P32 -> -0.50489334 | E34: ='SBUX Income Statement'!D31/'SBUX Balance Sheet'!Q32 -> -0.51589783 | F34: ='SBUX Income Statement'!E31/'SBUX Balance Sheet'!R32 -> -0.37690947 | G34: ='SBUX Income Statement'!F31/'SBUX Balance Sheet'!S32 -> -0.7891641 | H34: =+'SBUX Income Statement'!G31/'SBUX Balance Sheet'!T34 -> -0.11884826 | I34: =+'SBUX Income Statement'!H31/'SBUX Balance Sheet'!U34 -> -0.57740559 | J34: =+'SBUX Income Statement'!I31/'SBUX Balance Sheet'!V34 -> 8.3317572 | K34: =+'SBUX Income Statement'!J31/'SBUX Balance Sheet'!W34 -> 1.4629078 | L34: =+'SBUX Income Statement'!K31/'SBUX Balance Sheet'!X34 -> 3.4281388 | M34: =+'SBUX Income Statement'!L31/'SBUX Balance Sheet'!Y34 -> 3.1145078 | N34: =+'SBUX Income Statement'!M31/'SBUX Balance Sheet'!Z34 -> 2.8790771
B35: Return on Assets (not ave.) | D35: ='SBUX Income Statement'!C31/'SBUX Balance Sheet'!C35 -> 0.1182554 | E35: ='SBUX Income Statement'!D31/'SBUX Balance Sheet'!D35 -> 0.14007234 | F35: ='SBUX Income Statement'!E31/'SBUX Balance Sheet'!E35 -> 0.11729048 | G35: ='SBUX Income Statement'!F31/'SBUX Balance Sheet'!F35 -> 0.13376719 | H35: =+'SBUX Income Statement'!G31/'SBUX Balance Sheet'!G35 -> 0.03160224 | I35: =+'SBUX Income Statement'!H31/'SBUX Balance Sheet'!H35 -> 0.18726716 | J35: =+'SBUX Income Statement'!I31/'SBUX Balance Sheet'!I35 -> 0.40119803 | K35: =+'SBUX Income Statement'!J31/'SBUX Balance Sheet'!J35 -> 0.55430334 | L35: =+'SBUX Income Statement'!K31/'SBUX Balance Sheet'!K35 -> 1.4060644 | M35: =+'SBUX Income Statement'!L31/'SBUX Balance Sheet'!L35 -> 1.458937 | N35: =+'SBUX Income Statement'!M31/'SBUX Balance Sheet'!M35 -> 1.411117
B36: Return on Capital (not ave.) | D36: =('SBUX Income Statement'!C21-'SBUX Income Statement'!C28)/('SBUX Balance Sheet'!P32+'SBUX Balance Sheet'!P26) -> 0.13409613 | E36: =('SBUX Income Statement'!D21-'SBUX Income Statement'!D28)/('SBUX Balance Sheet'!Q32+'SBUX Balance Sheet'!Q26) -> 0.15604056 | F36: =('SBUX Income Statement'!E21-'SBUX Income Statement'!E28)/('SBUX Balance Sheet'!R32+'SBUX Balance Sheet'!R26) -> 0.13118464 | G36: =('SBUX Income Statement'!F21-'SBUX Income Statement'!F28)/('SBUX Balance Sheet'!S32+'SBUX Balance Sheet'!S26) -> 0.11838118 | H36: =(+'SBUX Income Statement'!G21-'SBUX Income Statement'!G28)/('SBUX Balance Sheet'!T19+'SBUX Balance Sheet'!T21+'SBUX Balance Sheet'!T32) -> 0.15474295 | I36: =(+'SBUX Income Statement'!H21-'SBUX Income Statement'!H28)/('SBUX Balance Sheet'!U19+'SBUX Balance Sheet'!U21+'SBUX Balance Sheet'!U32) -> 0.64973251 | J36: =(+'SBUX Income Statement'!I21-'SBUX Income Statement'!I28)/('SBUX Balance Sheet'!V19+'SBUX Balance Sheet'!V21+'SBUX Balance Sheet'!V32) -> 0.24706869 | K36: =(+'SBUX Income Statement'!J21-'SBUX Income Statement'!J28)/('SBUX Balance Sheet'!W19+'SBUX Balance Sheet'!W21+'SBUX Balance Sheet'!W32) -> 0.28798747 | L36: =(+'SBUX Income Statement'!K21-'SBUX Income Statement'!K28)/('SBUX Balance Sheet'!X19+'SBUX Balance Sheet'!X21+'SBUX Balance Sheet'!X32) -> 1.2245051 | M36: =(+'SBUX Income Statement'!L21-'SBUX Income Statement'!L28)/('SBUX Balance Sheet'!Y19+'SBUX Balance Sheet'!Y21+'SBUX Balance Sheet'!Y32) -> 1.243745 | N36: =(+'SBUX Income Statement'!M21-'SBUX Income Statement'!M28)/('SBUX Balance Sheet'!Z19+'SBUX Balance Sheet'!Z21+'SBUX Balance Sheet'!Z32) -> 1.2036802
B38: Market Measures
B39: Price Per share (last day of the year) | D39: =INDEX(_xlfn.STOCKHISTORY("SBUX", DATE(2024,12,30)), 2, 2) -> 90.58 | E39: =INDEX(_xlfn.STOCKHISTORY("SBUX", DATE(2023,12,29)), 2, 2) -> 96.01 | F39: =INDEX(_xlfn.STOCKHISTORY("SBUX", DATE(2024,12,30)), 2, 2) -> 90.58 | G39: =INDEX(_xlfn.STOCKHISTORY("SBUX", DATE(2024,12,31)), 2, 2) -> 91.25 | H39: 84.3 | I39: 88.37 | J39: 63.77 | K39: 53.86 | L39: 53.84 | M39: 55.77 | N39: 37.635
B40: EPS - Fully Diluted | D40: ='SBUX Income Statement'!C31/'SBUX Income Statement'!C37 -> 3.3068671 | E40: ='SBUX Income Statement'!D31/'SBUX Income Statement'!D37 -> 3.582472 | F40: ='SBUX Income Statement'!E31/'SBUX Income Statement'!E37 -> 2.8326284 | G40: ='SBUX Income Statement'!F31/'SBUX Income Statement'!F37 -> 3.5422185 | H40: =+'SBUX Income Statement'!G34 -> 0.79 | I40: =+'SBUX Income Statement'!H34 -> 2.9185858 | J40: =+'SBUX Income Statement'!I34 -> 6.9493045 | K40: =+'SBUX Income Statement'!J34 -> 5.4484434 | L40: =+'SBUX Income Statement'!K34 -> 1.9 | M40: =+'SBUX Income Statement'!L34 -> 1.82 | N40: =+'SBUX Income Statement'!M34 -> 1.35
B41: P/E | D41: =D39/D40 -> 27.391484 | E41: =E39/E40 -> 26.79993 | F41: =F39/F40 -> 31.977368 | G41: =G39/G40 -> 25.760692 | H41: =+H39/H40 -> 106.70886 | I41: =+I39/I40 -> 30.278363 | J41: =+J39/J40 -> 9.1764579 | K41: =+K39/K40 -> 9.8853923 | L41: =+L39/L40 -> 28.336842 | M41: =+M39/M40 -> 30.642857 | N41: =+N39/N40 -> 27.877778
B42: Dividend (annual) | D42: =-('SBUX Cash Flow'!D38) -> 2585 | E42: =-('SBUX Cash Flow'!E38) -> 2431.8 | F42: =-('SBUX Cash Flow'!F38) -> 2263.3 | G42: =-('SBUX Cash Flow'!G38) -> 2119 | H42: =0.41*4 -> 1.64 | I42: =0.36*4 -> 1.44 | J42: =0.3*4 -> 1.2 | K42: =0.25*4 -> 1 | L42: =0.2*4 -> 0.8 | M42: =0.16*4 -> 0.64 | N42: =0.13*4 -> 0.52
B43: Dividend Payout | D43: =D42/'SBUX Income Statement'!C31 -> 0.68733548 | E43: =E42/'SBUX Income Statement'!D31 -> 0.58959874 | F43: =F42/'SBUX Income Statement'!E31 -> 0.68969405 | G43: =G42/'SBUX Income Statement'!F31 -> 0.50460791 | H43: =+H42/H40 -> 2.0759494 | I43: =+I42/I40 -> 0.49338964 | J43: =+J42/J40 -> 0.17267915 | K43: =+K42/K40 -> 0.18353866 | L43: =+L42/L40 -> 0.42105263 | M43: =+M42/M40 -> 0.35164835 | N43: =+N42/N40 -> 0.38518519
B44: Dividend Yield | D44: =((D42/'SBUX Income Statement'!C36)/D39) -> 0.025170496 | E44: =((E42/'SBUX Income Statement'!D36)/E39) -> 0.022086337 | F44: =((F42/'SBUX Income Statement'!E36)/F39) -> 0.02166544 | G44: =((G42/'SBUX Income Statement'!F36)/G39) -> 0.019719699 | H44: =+H42/H39 -> 0.01945433 | I44: =+I42/I39 -> 0.016295123 | J44: =+J42/J39 -> 0.018817626 | K44: =+K42/K39 -> 0.018566654 | L44: =+L42/L39 -> 0.014858841 | M44: =+M42/M39 -> 0.011475704 | N44: =+N42/N39 -> 0.013816926
