Workbook

Sheet WALMART-Cash Flow Statements
A3: (Amounts in millions) | B3: 2025 | C3: 2024 | D3: 2023 | E3: 2022 | F3: 2021
A4: Cash flows from operating activities: Consolidated net income Adjustments to reconcile consolidated net income to net cash provided by operating activities: | B4: 20157 | C4: 16270 | D4: 11292 | E4: 13940 | F4: 13706
A5: Depreciation and amortization | B5: 12973 | C5: 11853 | D5: 10945 | E5: 10658 | F5: 11152
A6: Net unrealized and realized (gains) and losses | B6: 878 | C6: 3193 | D6: 1683 | E6: 2440 | F6: -8589
A7: Losses on disposal of business operations | E7: 433 | F7: 8401
A8: Deferred income taxes | B8: -635 | C8: -175 | D8: 449 | E8: -755 | F8: 1911
A9: Loss on extinguishment of debt | D9: 0 | E9: 2410 | F9: 0
A10: Other operating activities Changes in certain assets and liabilities, net of effects of acquisitions and dispositions: | B10: 2889 | C10: 2642 | D10: 1919 | E10: 1652 | F10: 1521
A11: Receivables, net | B11: -1106 | C11: -797 | D11: 240 | E11: -1796 | F11: -1086
A12: Inventories | B12: -2755 | C12: 2017 | D12: -528 | E12: -11764 | F12: -2395
A13: Accounts payable | B13: 3228 | C13: 2515 | D13: -1425 | E13: 5520 | F13: 6966
A14: Accrued liabilities | B14: 379 | C14: -1324 | D14: 4393 | E14: 1404 | F14: 4623
A15: Accrued income taxes | B15: 435 | C15: -468 | D15: -127 | E15: 39 | F15: -136
A16: Net cash provided by operating activities | B16: 36444 | C16: 35726 | D16: 28841 | E16: 24181 | F16: 36074
A17: Cash flows from investing activities: Payments for property and equipment | B17: -23783 | C17: -20606 | D17: -16857 | E17: -13106 | F17: -10264
A18: Proceeds from the disposal of property and equipment | B18: 432 | C18: 250 | D18: 170 | E18: 394 | F18: 215
A19: Proceeds from disposal of certain operations, net of divested cash | B19: 4080 | C19: 135 | E19: 7935 | F19: 56
A20: Payments for business acquisitions, net of cash acquired | B20: -1896 | C20: -9 | D20: -740 | E20: -359 | F20: -180
A21: Other investing activities | B21: -212 | C21: -1057 | D21: -295 | E21: -879 | F21: 102
A22: Net cash used in investing activities | B22: -21379 | C22: -21287 | D22: -17722 | E22: -6015 | F22: -10071
A23: Cash flows from financing activities: Net change in short-term borrowings | B23: 2212 | C23: 512 | D23: -34 | E23: 193 | F23: -324
A24: Proceeds from issuance of long-term debt | B24: 0 | C24: 4967 | D24: 5041 | E24: 6945 | F24: 0
A25: Repayments of long-term debt | B25: -3468 | C25: -4217 | D25: -2689 | E25: -13010 | F25: -5382
A26: Premiums paid to extinguish debt | E26: -2317 | F26: 0
A27: Dividends paid | B27: -6688 | C27: -6140 | D27: -6114 | E27: -6152 | F27: 6116
A28: Purchase of Company stock | B28: -4494 | C28: -2779 | D28: -9920 | E28: -9787 | F28: -2625
A29: Dividends paid to noncontrolling interest | B29: -576 | C29: -763 | D29: -444 | E29: -424 | F29: -434
A31: Purchase of noncontrolling interest | B31: 0 | C31: -3462 | D31: -827 | F31: 0
A32: Sale of subsidiary stock | B32: 362 | C32: 716 | D32: 66 | E32: 3239 | F32: 140
A33: Other financing activities | B33: -2170 | C33: -2248 | D33: -2118 | E33: -1515 | F33: -1376
A34: Net cash used in financing activities | B34: -14822 | C34: -13414 | D34: -17039 | E34: -22828 | F34: -16117
A35: Effect of exchange rates on cash, cash equivalents and restricted cash | B35: -641 | C35: 69 | D35: -73 | E35: -140 | F35: 235
A36: Net increase (decrease) in cash, cash equivalents and restricted cash | B36: -399 | C36: 1094 | D36: -5993 | E36: -4802 | F36: 10121
A37: Change in cash and cash equivalents reclassified from assets held for sale | E37: 1848 | F37: -1848
A38: Cash, cash equivalents and restricted cash at beginning of year | B38: 9935 | C38: 8841 | D38: 14834 | E38: 17788 | F38: 9515
A39: Cash, cash equivalents and restricted cash at end of year | B39: 9536 | C39: 9935 | D39: 8841 | E39: 14834 | F39: 17788

Sheet WALMART-Balance Sheet
B1: Walmart Inc. Consolidated Balance Sheets
D2: As of January 31,
A3: (Amounts in millions) ASSETS | C3: 2025 | D3: 2024 | E3: 2023 | F3: 2022 | G3: 2021
A5: Current assets: Cash and cash equivalents | C5: 9037 | D5: 9867 | E5: 8625 | F5: 14760 | G5: 17741
A6: Receivables, net | C6: 9975 | D6: 8796 | E6: 7933 | F6: 8280 | G6: 6516
A7: Inventories | C7: 56435 | D7: 54892 | E7: 56576 | F7: 56511 | G7: 44949
A8: Prepaid expenses and other | C8: 4011 | D8: 3322 | E8: 2521 | F8: 1519 | G8: 20861
A9: Total current assets | C9: 79458 | D9: 76877 | E9: 75655 | F9: 81070 | G9: 90067
A10: Property and equipment, net | C10: 119993 | D10: 110810 | E10: 100760 | F10: 94515 | G10: 92201
A11: Operating lease right-of-use assets | C11: 13599 | D11: 13673 | E11: 13555 | F11: 13758 | G11: 13642
A12: Finance lease right-of-use assets, net | C12: 6112 | D12: 5855 | E12: 4919 | F12: 4351 | G12: 4005
A13: Goodwill | C13: 28792 | D13: 28113 | E13: 28174 | F13: 29014 | G13: 28983
A14: Other long-term assets | C14: 12869 | D14: 17071 | E14: 20134 | F14: 22152 | G14: 23598
A15: Total assets | C15: 260823 | D15: 252399 | E15: 243197 | F15: 244860 | G15: 252496
... A27: Deferred income taxes and other | C27: 14398 | D27: 14629 | E27: 14688 | F27: 13474 | G27: 14370
A28: Commitments and contingencies Redeemable noncontrolling interest | C28: 271 | D28: 222 | E28: 237 | F28: 0
A29: Equity: Common stock | C29: 802 | D29: 805 | E29: 269 | F29: 276 | G29: 282
A30: Capital in excess of par value | C30: 5503 | D30: 4544 | E30: 4969 | F30: 4839 | G30: 3646
A31: Retained earnings | C31: 98313 | D31: 89814 | E31: 83135 | F31: 86904 | G31: 88763
A32: Accumulated other comprehensive loss | C32: -13605 | D32: -11302 | E32: -11680 | F32: -8766 | G32: -11766
A33: Total Walrnart shareholders' equity | C33: 91013 | D33: 83861 | E33: 76693 | F33: 83253 | G33: 80925
A34: Noncontrolling interest | C34: 6408 | D34: 6488 | E34: 7061 | F34: 8638 | G34: 6606
A35: Total equity | C35: 97421 | D35: 90349 | E35: 83754 | F35: 91891 | G35: 87531
A36: Total liabilities, redeemable noncontrolling interest, and equity | C36: 260823 | D36: 252399 | E36: 243197 | F36: 244860 | G36: 252496

Sheet WALMART-Income Statement
B1: Walmart Inc.
B2: Consolidated Statements of Income
A4: (Amounts in millions, except per share data) Revenues: | C4: 2025 | D4: 2024 | E4: 2023 | F4: 2022 | G4: 2021
A6: Net sales | C6: 674538 | D6: 642637 | E6: 605881 | F6: 567762 | G6: 555233
A7: Membership and other income | C7: 6447 | D7: 5488 | E7: 5408 | F7: 4992 | G7: 3918
A8: Total revenues Costs and expenses: | C8: 680985 | D8: 648125 | E8: 611289 | F8: 572754 | G8: 559151
A9: Cost of sales | C9: 511753 | D9: 490142 | E9: 463721 | F9: 429000 | G9: 420315
A10: Operating, selling, general and administrative expenses | C10: 139884 | D10: 130971 | E10: 127140 | F10: 117812 | G10: 116288
A11: Operating income Interest: | C11: 29348 | D11: 27012 | E11: 20428 | F11: 25942 | G11: 22548
A12: Debt | C12: 2249 | D12: 2259 | E12: 1787 | F12: 1674 | G12: 1976
A13: Finance lease | C13: 479 | D13: 424 | E13: 341 | F13: 320 | G13: 339
A14: Interest income | C14: -483 | D14: -546 | E14: -254 | F14: -158 | G14: -121
A15: Interest, net | C15: 2245 | D15: 2137 | E15: 1874 | F15: 1836 | G15: 2194
A16: Loss on extinguishment of debt | F16: 2410
A17: Other (gains) and losses | C17: 794 | D17: 3027 | E17: 1538 | F17: 3000 | G17: 210
A18: Income before income taxes | C18: 26309 | D18: 21848 | E18: 17016 | F18: 18696 | G18: 20564
A19: Provision for income taxes | C19: 6152 | D19: 5578 | E19: 5724 | F19: 4756 | G19: 6858
A20: Consolidated net income | C20: 20157 | D20: 16270 | E20: 11292 | F20: 13940 | G20: 13706
A21: Consolidated net (income) loss attributable to noncontrolling interest | C21: -721 | D21: -759 | E21: 388 | F21: -267 | G21: -196
A22: Consolidated net income attributable to Walmart | C22: 19436 | D22: 15511 | E22: 11680 | F22: 13673 | G22: 13510
A23: Net income per common share: Basic net income per common share attributable to Walrnart | C23: 2.42 | D23: 1.92 | E23: 1.43 | F23: 1.63 | G23: 4.77
A24: Diluted net income per common share attributable to Walmart | C24: 2.41 | D24: 1.91 | E24: 1.42 | F24: 1.62 | G24: 4.75
A25: Weighted-average common shares outstanding: Basic | C25: 8041 | D25: 8077 | E25: 8171 | F25: 8376 | G25: 2831
A26: Diluted | C26: 8081 | D26: 8108 | E26: 8202 | F26: 8415 | G26: 2847
A27: Dividends declared per common share See accompanying notes. | C27: 0.83 | D27: 0.76 | E27: 0.7467 | F27: 0.7333 | G27: 2.16

Sheet WALMART-Ratios 
A1: Profitability
A2: Years | B2: 2025 | C2: 2024 | D2: 2023 | E2: 2022 | F2: 2021
A3: Gross Profit Margin= gross profit/ sales | B3: =('WALMART-Income Statement'!C6-'WALMART-Income Statement'!C9)/'WALMART-Income Statement'!C6 -> 0.24132814 | C3: =('WALMART-Income Statement'!D6-'WALMART-Income Statement'!D9)/'WALMART-Income Statement'!D6 -> 0.23729571 | D3: =('WALMART-Income Statement'!E6-'WALMART-Income Statement'!E9)/'WALMART-Income Statement'!E6 -> 0.23463353 | E3: =('WALMART-Income Statement'!F6-'WALMART-Income Statement'!F9)/'WALMART-Income Statement'!F6 -> 0.2444017 | F3: =('WALMART-Income Statement'!G6-'WALMART-Income Statement'!G9)/'WALMART-Income Statement'!G6 -> 0.24299348
A4: Operating Profit Margin = Operating profit/ sales | B4: ='WALMART-Income Statement'!C11/'WALMART-Income Statement'!C6 -> 0.043508298 | C4: ='WALMART-Income Statement'!D11/'WALMART-Income Statement'!D6 -> 0.042033061 | D4: ='WALMART-Income Statement'!E11/'WALMART-Income Statement'!E6 -> 0.033716192 | E4: ='WALMART-Income Statement'!F11/'WALMART-Income Statement'!F6 -> 0.045691681 | F4: ='WALMART-Income Statement'!G11/'WALMART-Income Statement'!G6 -> 0.040609978
A5: Net Profit Margin = net profit/ sales | B5: ='WALMART-Income Statement'!C22/'WALMART-Income Statement'!C6 -> 0.028813796 | C5: ='WALMART-Income Statement'!D22/'WALMART-Income Statement'!D6 -> 0.024136488 | D5: ='WALMART-Income Statement'!E22/'WALMART-Income Statement'!E6 -> 0.019277713 | E5: ='WALMART-Income Statement'!F22/'WALMART-Income Statement'!F6 -> 0.024082274 | F5: ='WALMART-Income Statement'!G22/'WALMART-Income Statement'!G6 -> 0.024332127
A7: Efficiency
A8: AR Days on Hand= (AR/Sales)*365 | B8: =('WALMART-Balance Sheet'!C6/'WALMART-Income Statement'!C6)*365 -> 5.3975832 | C8: =('WALMART-Balance Sheet'!D6/'WALMART-Income Statement'!D6)*365 -> 4.9958841 | D8: =('WALMART-Balance Sheet'!E6/'WALMART-Income Statement'!E6)*365 -> 4.7790655 | E8: =('WALMART-Balance Sheet'!F6/'WALMART-Income Statement'!F6)*365 -> 5.3230051 | F8: =('WALMART-Balance Sheet'!G6/'WALMART-Income Statement'!G6)*365 -> 4.283499
A9: Inventory Days on Hand= (Inventory/COGS)*365 | B9: =('WALMART-Balance Sheet'!C7/'WALMART-Income Statement'!C9)*365 -> 40.251401 | C9: =('WALMART-Balance Sheet'!D7/'WALMART-Income Statement'!D9)*365 -> 40.877093 | D9: =('WALMART-Balance Sheet'!E7/'WALMART-Income Statement'!E9)*365 -> 44.531604 | E9: =('WALMART-Balance Sheet'!F7/'WALMART-Income Statement'!F9)*365 -> 48.080455 | F9: =('WALMART-Balance Sheet'!G7/'WALMART-Income Statement'!G9)*365 -> 39.033546
A10: AP Days on Hand= (AP*365)/COGS | B10: =('WALMART-Balance Sheet'!C17*365)/'WALMART-Income Statement'!C9 -> 41.842627 | C10: =('WALMART-Balance Sheet'!D17*365)/'WALMART-Income Statement'!D9 -> 42.306882 | D10: =('WALMART-Balance Sheet'!E17*365)/'WALMART-Income Statement'!E9 -> 42.300931 | E10: =('WALMART-Balance Sheet'!F17*365)/'WALMART-Income Statement'!F9 -> 47.016935 | F10: =('WALMART-Balance Sheet'!G17*365)/'WALMART-Income Statement'!G9 -> 42.673864
A11: Asset Turnover = Sales/ Total Assets | B11: ='WALMART-Income Statement'!C6/'WALMART-Balance Sheet'!C15 -> 2.5861906 | C11: ='WALMART-Income Statement'!D6/'WALMART-Balance Sheet'!D15 -> 2.5461155 | D11: ='WALMART-Income Statement'!E6/'WALMART-Balance Sheet'!E15 -> 2.4913177 | E11: ='WALMART-Income Statement'!F6/'WALMART-Balance Sheet'!F15 -> 2.3187209 | F11: ='WALMART-Income Statement'!G6/'WALMART-Balance Sheet'!G15 -> 2.1989774
A13: Leverage
A14: Debt/ Equity | B14: =('WALMART-Balance Sheet'!C16+'WALMART-Balance Sheet'!C24)/'WALMART-Balance Sheet'!C35 -> 0.37434434 | C14: =('WALMART-Balance Sheet'!D16+'WALMART-Balance Sheet'!D24)/'WALMART-Balance Sheet'!D35 -> 0.40963375 | D14: =('WALMART-Balance Sheet'!E16+'WALMART-Balance Sheet'!E24)/'WALMART-Balance Sheet'!E35 -> 0.41814122 | E14: =('WALMART-Balance Sheet'!F16+'WALMART-Balance Sheet'!F24)/'WALMART-Balance Sheet'!F35 -> 0.38386784 | F14: =('WALMART-Balance Sheet'!G16+'WALMART-Balance Sheet'!G24)/'WALMART-Balance Sheet'!G35 -> 0.47318093
A15: Liabilities/ Equity | B15: ='WALMART-Balance Sheet'!C36/'WALMART-Balance Sheet'!C35 -> 2.677277 | C15: ='WALMART-Balance Sheet'!D36/'WALMART-Balance Sheet'!D35 -> 2.7936004 | D15: ='WALMART-Balance Sheet'!E36/'WALMART-Balance Sheet'!E35 -> 2.9037061 | E15: ='WALMART-Balance Sheet'!F36/'WALMART-Balance Sheet'!F35 -> 2.6646788 | F15: ='WALMART-Balance Sheet'!G36/'WALMART-Balance Sheet'!G35 -> 2.8846466
A16: LTD/ Total Captial = LTD/(STD+LTD+SE) | B16: ='WALMART-Balance Sheet'!C24/'WALMART-Ratios '!B32 -> 0.24946598 | C16: ='WALMART-Balance Sheet'!D24/'WALMART-Ratios '!C32 -> 0.28370198 | D16: ='WALMART-Balance Sheet'!E24/'WALMART-Ratios '!D32 -> 0.29171964 | E16: ='WALMART-Balance Sheet'!F24/'WALMART-Ratios '!E32 -> 0.27416349 | F16: ='WALMART-Balance Sheet'!G24/'WALMART-Ratios '!F32 -> 0.31945963
A17: Debt/ EBITDA | B17: =('WALMART-Balance Sheet'!C16+'WALMART-Balance Sheet'!C24)/('WALMART-Income Statement'!C11+'WALMART-Cash Flow Statements'!B5) -> 0.86172349 | C17: =('WALMART-Balance Sheet'!D16+'WALMART-Balance Sheet'!D24)/('WALMART-Income Statement'!D11+'WALMART-Cash Flow Statements'!C5) -> 0.95227068 | D17: =('WALMART-Balance Sheet'!E16+'WALMART-Balance Sheet'!E24)/('WALMART-Income Statement'!E11+'WALMART-Cash Flow Statements'!D5) -> 1.1162783 | E17: =('WALMART-Balance Sheet'!F16+'WALMART-Balance Sheet'!F24)/('WALMART-Income Statement'!F11+'WALMART-Cash Flow Statements'!E5) -> 0.96377049 | F17: =('WALMART-Balance Sheet'!G16+'WALMART-Balance Sheet'!G24)/('WALMART-Income Statement'!G11+'WALMART-Cash Flow Statements'!F5) -> 1.2290208
A18: Times Interest Earned | B18: ='WALMART-Income Statement'!C11/('WALMART-Income Statement'!C15) -> 13.072606 | C18: ='WALMART-Income Statement'!D11/('WALMART-Income Statement'!D15) -> 12.64015 | D18: ='WALMART-Income Statement'!E11/('WALMART-Income Statement'!E15) -> 10.900747 | E18: ='WALMART-Income Statement'!F11/('WALMART-Income Statement'!F15) -> 14.12963 | F18: ='WALMART-Income Statement'!G11/('WALMART-Income Statement'!G15) -> 10.277119
A19: FCCR= (EBITDA + Rent)/(Rent + Interest Expense) | B19: =('WALMART-Income Statement'!C11+'WALMART-Cash Flow Statements'!B5)/'WALMART-Income Statement'!C15 -> 18.851225 | C19: =('WALMART-Income Statement'!D11+'WALMART-Cash Flow Statements'!C5)/'WALMART-Income Statement'!D15 -> 18.18671 | D19: =('WALMART-Income Statement'!E11+'WALMART-Cash Flow Statements'!D5)/'WALMART-Income Statement'!E15 -> 16.741195 | E19: =('WALMART-Income Statement'!F11+'WALMART-Cash Flow Statements'!E5)/'WALMART-Income Statement'!F15 -> 19.934641 | F19: =('WALMART-Income Statement'!G11+'WALMART-Cash Flow Statements'!F5)/'WALMART-Income Statement'!G15 -> 15.360073
A21: Liquidity
A22: Current Ratio= Current asset/ Current liabilities | B22: ='WALMART-Balance Sheet'!C9/'WALMART-Balance Sheet'!C23 -> 0.82268285 | C22: ='WALMART-Balance Sheet'!D9/'WALMART-Balance Sheet'!D23 -> 0.83186712 | D22: ='WALMART-Balance Sheet'!E9/'WALMART-Balance Sheet'!E23 -> 0.82057095 | E22: ='WALMART-Balance Sheet'!F9/'WALMART-Balance Sheet'!F23 -> 0.9277973 | F22: ='WALMART-Balance Sheet'!G9/'WALMART-Balance Sheet'!G23 -> 0.97217335
A23: Quick Ratio= (Current assets-inventory)/Current Liabilities | B23: =('WALMART-Balance Sheet'!C9-'WALMART-Balance Sheet'!C7)/'WALMART-Balance Sheet'!C23 -> 0.23837282 | C23: =('WALMART-Balance Sheet'!D9-'WALMART-Balance Sheet'!D7)/'WALMART-Balance Sheet'!D23 -> 0.23789428 | D23: =('WALMART-Balance Sheet'!E9-'WALMART-Balance Sheet'!E7)/'WALMART-Balance Sheet'!E23 -> 0.20693507 | E23: =('WALMART-Balance Sheet'!F9-'WALMART-Balance Sheet'!F7)/'WALMART-Balance Sheet'!F23 -> 0.28106296 | F23: =('WALMART-Balance Sheet'!G9-'WALMART-Balance Sheet'!G7)/'WALMART-Balance Sheet'!G23 -> 0.48699876
A24: Cash Conversion Cycle= DSO+DIO-DPO | B24: =B8+B9-B10 -> 3.8063566 | C24: =C8+C9-C10 -> 3.5660944 | D24: =D8+D9-D10 -> 7.0097387 | E24: =E8+E9-E10 -> 6.3865249 | F24: =F8+F9-F10 -> 0.64318162
A26: Returns
A27: ROE= NI/ SE | B27: ='WALMART-Income Statement'!C22/'WALMART-Balance Sheet'!C35 -> 0.19950524 | C27: ='WALMART-Income Statement'!D22/'WALMART-Balance Sheet'!D35 -> 0.17167871 | D27: ='WALMART-Income Statement'!E22/'WALMART-Balance Sheet'!E35 -> 0.13945603 | E27: ='WALMART-Income Statement'!F22/'WALMART-Balance Sheet'!F35 -> 0.14879586 | F27: ='WALMART-Income Statement'!G22/'WALMART-Balance Sheet'!G35 -> 0.15434532
A28: ROA= NI/ Total Assets | B28: ='WALMART-Income Statement'!C22/'WALMART-Balance Sheet'!C15 -> 0.074517968 | C28: ='WALMART-Income Statement'!D22/'WALMART-Balance Sheet'!D15 -> 0.061454285 | D28: ='WALMART-Income Statement'!E22/'WALMART-Balance Sheet'!E15 -> 0.048026908 | E28: ='WALMART-Income Statement'!F22/'WALMART-Balance Sheet'!F15 -> 0.055840072 | F28: ='WALMART-Income Statement'!G22/'WALMART-Balance Sheet'!G15 -> 0.053505798
A29: ROC= NOPAT/ Captial | B29: =('WALMART-Income Statement'!C11*(1-B31)/B32) -> 0.16793914 | C29: =('WALMART-Income Statement'!D11*(1-C31)/C32) -> 0.15794394 | D29: =('WALMART-Income Statement'!E11*(1-D31)/D32) -> 0.11413378 | E29: =('WALMART-Income Statement'!F11*(1-E31)/E32) -> 0.15210726 | F29: =('WALMART-Income Statement'!G11*(1-F31)/F32) -> 0.11654487
A31: Tax Rate | B31: ='WALMART-Income Statement'!C19/'WALMART-Income Statement'!C18 -> 0.23383633 | C31: ='WALMART-Income Statement'!D19/'WALMART-Income Statement'!D18 -> 0.25530941 | D31: ='WALMART-Income Statement'!E19/'WALMART-Income Statement'!E18 -> 0.33638928 | E31: ='WALMART-Income Statement'!F19/'WALMART-Income Statement'!F18 -> 0.25438596 | F31: ='WALMART-Income Statement'!G19/'WALMART-Income Statement'!G18 -> 0.33349543
A32: Invested Captial | B32: =('WALMART-Balance Sheet'!C16+'WALMART-Balance Sheet'!C24+'WALMART-Balance Sheet'!C5+'WALMART-Balance Sheet'!C35)-'WALMART-Balance Sheet'!C5 -> 133890 | C32: =('WALMART-Balance Sheet'!D16+'WALMART-Balance Sheet'!D24+'WALMART-Balance Sheet'!D5+'WALMART-Balance Sheet'!D35)-'WALMART-Balance Sheet'!D5 -> 127359 | D32: =('WALMART-Balance Sheet'!E16+'WALMART-Balance Sheet'!E24+'WALMART-Balance Sheet'!E5+'WALMART-Balance Sheet'!E35)-'WALMART-Balance Sheet'!E5 -> 118775 | E32: =('WALMART-Balance Sheet'!F16+'WALMART-Balance Sheet'!F24+'WALMART-Balance Sheet'!F5+'WALMART-Balance Sheet'!F35)-'WALMART-Balance Sheet'!F5 -> 127165 | F32: =('WALMART-Balance Sheet'!G16+'WALMART-Balance Sheet'!G24+'WALMART-Balance Sheet'!G5+'WALMART-Balance Sheet'!G35)-'WALMART-Balance Sheet'!G5 -> 128949
A34: Market Metrics
A35: EPS = NI/ Share Outstanding | B35: ='WALMART-Income Statement'!C22/'WALMART-Income Statement'!C25 -> 2.4171123 | C35: ='WALMART-Income Statement'!D22/'WALMART-Income Statement'!D25 -> 1.9203912 | D35: ='WALMART-Income Statement'!E22/'WALMART-Income Statement'!E25 -> 1.4294456 | E35: ='WALMART-Income Statement'!F22/'WALMART-Income Statement'!F25 -> 1.6324021 | F35: ='WALMART-Income Statement'!G22/'WALMART-Income Statement'!G25 -> 4.7721653
A36: PE= Price-to-Earnings | B36: =C43/B35 -> 41.276527 | C36: =C45/C35 -> 47.047705 | D36: =C47/D35 -> 36.762154 | E36: =C47/E35 -> 32.191517 | F36: =C52/F35 -> 424.12613
A37: PB= Price-to-Book | B37: ='WALMART-Balance Sheet'!C35/'WALMART-Income Statement'!C25 -> 12.115533 | C37: ='WALMART-Balance Sheet'!D35/'WALMART-Income Statement'!D25 -> 11.18596 | D37: ='WALMART-Balance Sheet'!E35/'WALMART-Income Statement'!E25 -> 10.250153 | E37: ='WALMART-Balance Sheet'!F35/'WALMART-Income Statement'!F25 -> 10.97075 | F37: ='WALMART-Balance Sheet'!G35/'WALMART-Income Statement'!G25 -> 30.918757
A38: Dividend Yield | B38: =('WALMART-Income Statement'!C27/'WALMART-Ratios '!C43) -> 0.008319134 | C38: =('WALMART-Income Statement'!D27/'WALMART-Ratios '!C45) -> 0.0084117322 | D38: =('WALMART-Income Statement'!E27/'WALMART-Ratios '!C47) -> 0.01420946 | E38: =('WALMART-Income Statement'!F27/'WALMART-Ratios '!C49) -> 0.015515341 | F38: =('WALMART-Income Statement'!G27/'WALMART-Ratios '!C52) -> 0.0010671937
A39: Market Capitalization | B39: =C43*'WALMART-Income Statement'!C26 -> 806241.37 | C39: =C45*'WALMART-Income Statement'!D26 -> 732557.8 | D39: =C47*'WALMART-Income Statement'!E26 -> 431011 | E39: =C49*'WALMART-Income Statement'!F25 -> 395874.05 | F39: =C52*'WALMART-Income Statement'!G26 -> 5762328
A40: EV/EBITDA | B40: =(B39+ 'WALMART-Balance Sheet'!C24+'WALMART-Balance Sheet'!C16+'WALMART-Income Statement'!C21-'WALMART-Balance Sheet'!C5)/('WALMART-Income Statement'!C11+'WALMART-Cash Flow Statements'!B5) -> 19.681774 | C40: =(C39+ 'WALMART-Balance Sheet'!D24+'WALMART-Balance Sheet'!D16+'WALMART-Income Statement'!D21-'WALMART-Balance Sheet'!D5)/('WALMART-Income Statement'!D11+'WALMART-Cash Flow Statements'!C5) -> 19.527642 | D40: =(D39+ 'WALMART-Balance Sheet'!E24+'WALMART-Balance Sheet'!E16+'WALMART-Income Statement'!E21-'WALMART-Balance Sheet'!E5)/('WALMART-Income Statement'!E11+'WALMART-Cash Flow Statements'!D5) -> 14.592006 | E40: =(E39+ 'WALMART-Balance Sheet'!F24+'WALMART-Balance Sheet'!F16+'WALMART-Income Statement'!F21-'WALMART-Balance Sheet'!F5)/('WALMART-Income Statement'!F11+'WALMART-Cash Flow Statements'!E5) -> 11.369428 | F40: =(F39+ 'WALMART-Balance Sheet'!G24+'WALMART-Balance Sheet'!G16+'WALMART-Income Statement'!G21-'WALMART-Balance Sheet'!G5)/('WALMART-Income Statement'!G11+'WALMART-Cash Flow Statements'!F5) -> 171.68573
A42: Stock prices | B42: {=_xlfn.STOCKHISTORY("WMT", TODAY()-1, TODAY())} -> Date | C42: Close
B43: 45810 | C43: 99.77
B44: {=_xlfn.STOCKHISTORY("WMT", DATE(2024,12,31), DATE(2024,12,31), 0, 1)} -> Date | C44: Close
B45: 45657 | C45: 90.35
B46: {=_xlfn.STOCKHISTORY("WMT", DATE(2023,12,29), DATE(2023,12,29), 0, 1)} -> Date | C46: Close
B47: 45289 | C47: 52.5495
...

Sheet Trend Analysis-5 Years

Sheet WALMART-DuPont Model
A1: DuPont Model
A3: Profitability | B3: x | C3: Efficiency | D3: x | E3: leverage | F3: = | G3: Retun
A4: Net Income/Sales | C4: Sales/Total Assets | E4: Total Assets/ Equity | G4: Income/Equity
A6: Walmart DuPont | B6: 2025 | C6: 2024 | D6: 2023 | E6: 2022 | F6: 2021
A7: PROFITABILITY | B7: ='WALMART-Income Statement'!C22/'WALMART-Income Statement'!C6 -> 0.028813796 | C7: ='WALMART-Income Statement'!D22/'WALMART-Income Statement'!D6 -> 0.024136488 | D7: ='WALMART-Income Statement'!E22/'WALMART-Income Statement'!E6 -> 0.019277713 | E7: ='WALMART-Income Statement'!F22/'WALMART-Income Statement'!F6 -> 0.024082274 | F7: ='WALMART-Income Statement'!G22/'WALMART-Income Statement'!G6 -> 0.024332127
A8: EFFICIENCY | B8: ='WALMART-Income Statement'!C6/'WALMART-Balance Sheet'!C15 -> 2.5861906 | C8: ='WALMART-Income Statement'!D6/'WALMART-Balance Sheet'!D15 -> 2.5461155 | D8: ='WALMART-Income Statement'!E6/'WALMART-Balance Sheet'!E15 -> 2.4913177 | E8: ='WALMART-Income Statement'!F6/'WALMART-Balance Sheet'!F15 -> 2.3187209 | F8: ='WALMART-Income Statement'!G6/'WALMART-Balance Sheet'!G15 -> 2.1989774
A9: LEVERAGE | B9: ='WALMART-Balance Sheet'!C15/'WALMART-Balance Sheet'!C35 -> 2.677277 | C9: ='WALMART-Balance Sheet'!D15/'WALMART-Balance Sheet'!D35 -> 2.7936004 | D9: ='WALMART-Balance Sheet'!E15/'WALMART-Balance Sheet'!E35 -> 2.9037061 | E9: ='WALMART-Balance Sheet'!F15/'WALMART-Balance Sheet'!F35 -> 2.6646788 | F9: ='WALMART-Balance Sheet'!G15/'WALMART-Balance Sheet'!G35 -> 2.8846466
A10: RETURN(ROE) | B10: =B7*B8*B9 -> 0.19950524 | C10: =C7*C8*C9 -> 0.17167871 | D10: =D7*D8*D9 -> 0.13945603 | E10: =E7*E8*E9 -> 0.14879586 | F10: =F7*F8*F9 -> 0.15434532

Sheet TARGET LTD, STATEMENTS & DuPont
A1: Balance sheet | I1: Consolidated Statements of Cash Flows | Q1: Income Statement
A2: (millions, except footnotes) Assets | C2: 2025 | D2: 2024 | E2: 2023 | F2: 2022 | G2: 2021 | I2: (millions) | K2: 2025 | L2: 2024 | M2: 2023 | N2: 2022 | O2: 2021 | Q2: (millions, except per share data) | S2: 2025 | T2: 2024 | U2: 2023 | V2: 2022 | W2: 2021
A3: Cash and cash equivalents | B3: $ | C3: 4762 | D3: 3805 | E3: 2229 | F3: 5911 | G3: 8511 | I3: Operating activities Net earnings Adjustments to reconcile net earnings to cash provided by operations: | J3: $ | K3: 4,091 $ | L3: 4,138 $ | M3: 2780 | N3: 6946 | O3: 4368 | Q3: Net sales | R3: $ | S3: 106566 | T3: 107412 | U3: 109120 | V3: 106005 | W3: 93561
A4: Inventory | C4: 12740 | D4: 11886 | E4: 13499 | F4: 13902 | G4: 10653 | I4: Depreciation and amortization | K4: 2981 | L4: 2801 | M4: 2700 | N4: 2642 | O4: 2485 | Q4: Cost of sales | S4: 76502 | T4: 77828 | U4: 82306 | V4: 74963 | W4: 66177
A5: Other current assets | C5: 1952 | D5: 1807 | E5: 2118 | F5: 1760 | G5: 1592 | I5: Share-based compensation expense | K5: 304 | L5: 251 | M5: 220 | N5: 228 | O5: 200 | Q5: Selling, general, and administrative expenses | S5: 21969 | T5: 21462 | U5: 20581 | V5: 19752 | W5: 18615
A6: Total current assets | C6: 19454 | D6: 17498 | E6: 17846 | F6: 21573 | G6: 20756 | I6: Deferred income taxes | K6: -180 | L6: 298 | M6: 582 | N6: 522 | O6: -184 | Q6: Depreciation and amortization (exclusive of depreciation included in cost of sales) | S6: 2529 | T6: 2415 | U6: 2385 | V6: 2344 | W6: 2230
I7: Gain on Dermstore sale | N7: -335 | O7: 0
O8: 512
A9: Property and equipment Land | C9: 6735 | D9: 6547 | E9: 6231 | F9: 6164 | G9: 6141 | I9: Noncash losses / (gains) and other, net | K9: 26 | L9: 94 | M9: 172 | N9: 67 | O9: 86 | Q9: Operating income | S9: 5566 | T9: 5707 | U9: 3848 | V9: 8946 | W9: 6539
A10: Buildings and improvements | C10: 38752 | D10: 37066 | E10: 34746 | F10: 32985 | G10: 31557 | I10: Changes in operating accounts: Inventory | K10: -854 | L10: 1613 | M10: 403 | N10: -3249 | O10: -1661 | Q10: Net interest expense | S10: 411 | T10: 502 | U10: 478 | V10: 421 | W10: 977
A11: Fixtures and equipment | C11: 8917 | D11: 8765 | E11: 7439 | F11: 6407 | G11: 5914 | I11: Other assets | K11: -308 | L11: -85 | M11: 22 | N11: -78 | O11: -137 | Q11: Net other income | S11: -106 | T11: -92 | U11: -48 | V11: -382 | W11: 16
A12: Computer hardware and software | C12: 3710 | D12: 3428 | E12: 3039 | F12: 2505 | G12: 2765 | I12: Accounts payable | K12: 1008 | L12: -1216 | M12: -2237 | N12: 2628 | O12: 2925 | Q12: Earnings before income taxes | S12: 5261 | T12: 5297 | U12: 3418 | V12: 8907 | W12: 5546
A13: Construction-in-progress | C13: 1185 | D13: 1703 | E13: 2688 | F13: 1257 | G13: 780 | I13: Accrued and other liabilities | K13: 299 | L13: 727 | M13: -624 | N13: -746 | O13: 1931 | Q13: Provision for income taxes | S13: 1170 | T13: 1159 | U13: 638 | V13: 1961 | W13: 1178
A14: Accumulated depreciation | C14: -26277 | D14: -24413 | E14: -22631 | F14: -21137 | G14: -20278 | I14: Cash provided by operating activities | K14: 7367 | L14: 8621 | M14: 4018 | N14: 8625 | O14: 10525 | Q14: Net earnings | R14: $ | S14: 4091 | T14: 4138 | U14: 2780 | V14: 6946 | W14: 4368
A15: Property and equipment, net | C15: 33022 | D15: 33096 | E15: 31512 | F15: 28181 | G15: 26879 | I15: Investing activities Expenditures for property and equipment | K15: -2891 | L15: -4806 | M15: -5528 | N15: 3544 | O15: -2649 | Q15: Basic earnings per share | R15: $ | S15: 8.89 | T15: 8.96 | U15: 6.02 | V15: 14.23 | W15: 8.72
A16: Operating lease assets | C16: 3763 | D16: 3362 | E16: 2657 | F16: 2556 | G16: 2227 | I16: Proceeds from disposal of property and equipment | K16: 3 | L16: 24 | M16: 8 | N16: 27 | O16: 42 | Q16: Diluted earnings per share Weighted average common shares outstanding | R16: $ | S16: 8.86 | T16: 8.94 | U16: 5.98 | V16: 14.1 | W16: 8.64
I17: Proceeds from Dermstore sale | N17: 356 | O17: 0
A18: Other noncurrent assets | C18: 1530 | D18: 1400 | E18: 1320 | F18: 1501 | G18: 1386 | I18: Other investments | K18: 28 | L18: 22 | M18: 16 | N18: 7 | O18: 16 | Q18: Basic | S18: 460.4 | T18: 461.5 | U18: 462.1 | V18: 488.1 | W18: 500.6
A20: Total assets | B20: $ | C20: 57769 | D20: 55356 | E20: 53335 | F20: 53811 | G20: 51248 | I20: Cash required for investing activities | K20: -2860 | L20: -4760 | M20: -5504 | N20: -3154 | O20: -2591 | Q20: Diluted | S20: 461.8 | T20: 462.8 | U20: 464.7 | V20: 492.7 | W20: 505.4
A21: Liabilities and shareholders' investment Accounts payable | B21: $ | C21: 13053 | D21: 12098 | E21: 13487 | F21: 15478 | G21: 12859 | I21: Financing activities Additions to long-term debt | K21: 741 | M21: 2625 | N21: 1972 | O21: 2480 | Q21: Antidilutive shares | S21: 0.5 | T21: 2.1 | U21: 1.1 | V21: 0 | W21: 0
A22: Accrued and other current liabilities | C22: 6110 | D22: 6090 | E22: 5883 | F22: 6098 | G22: 6122 | I22: Reductions of long-term debt | K22: -1139 | L22: -147 | M22: -163 | N22: -1147 | O22: -2415
A23: Current portion of long-term debt and other borrowings | C23: 1636 | D23: 1116 | E23: 130 | F23: 171 | G23: 1144 | I23: Dividends paid | K23: -2046 | L23: -2011 | M23: -1836 | N23: -1548 | O23: -1343
A24: Total current liabilities | C24: 20799 | D24: 19304 | E24: 19500 | F24: 21747 | G24: 20125 | I24: Repurchase of stock | K24: -1007 | M24: -2646 | N24: -7188 | O24: -745
A25: Long-term debt and other borrowings | C25: 14304 | D25: 14922 | E25: 16009 | F25: 13549 | G25: 11536 | I25: Shares withheld for taxes on share-based compensation | K25: -99 | L25: -127 | M25: -180 | N25: -168
A26: Noncurrent operating lease liabilities | C26: 3582 | D26: 3279 | E26: 2638 | F26: 2493 | G26: 2218 | I26: Stock option exercises | M26: 4 | N26: 8 | O26: 23
A27: Deferred income taxes | C27: 2303 | D27: 2480 | E27: 2196 | F27: 1566 | G27: 990 | I27: Cash required for financing activities | K27: -3550 | L27: -2285 | M27: -2196 | N27: -8071 | O27: -2000
A28: Other noncurrent liabilities | C28: 2115 | D28: 1939 | E28: 1760 | F28: 1629 | G28: 1939 | I28: Net increase / (decrease) in cash and cash equivalents | K28: 957 | L28: 1576 | M28: -3682 | N28: -2600 | O28: 5934
I29: Cash and cash equivalents at beginning of period | K29: 3805 | L29: 2229 | M29: 5911 | N29: 8511 | O29: 2577
A30: Total noncurrent liabilities Shareholders' investment | C30: 22304 | D30: 22620 | E30: 22603 | F30: 19237 | G30: 16683 | I30: Cash and cash equivalents at end of period | J30: $ | K30: 4,762 $ | L30: 3,805 $ | M30: 2229 | N30: 5911 | O30: 8511
A31: Common stock | C31: 38 | D31: 38 | E31: 38 | F31: 39 | G31: 42 | I31: Supplemental information Interest paid, net of capitalized interest | J31: $ | K31: 615 $ | L31: 605 $ | M31: 449 | N31: 414 | O31: 939
A32: Additional paid-in capital | C32: 6996 | D32: 6761 | E32: 6608 | F32: 6421 | G32: 6329 | I32: Income taxes paid | K32: 1055 | L32: 374 | M32: 213 | N32: 2063 | O32: 1031
A33: Retained earnings | C33: 8090 | D33: 7093 | E33: 5005 | F33: 6920 | G33: 8825 | I33: Leased assets obtained in exchange for new finance lease liabilities | K33: 319 | L33: 104 | M33: 224 | N33: 288 | O33: 428
A34: Accumulated other comprehensive loss | C34: -458 | D34: -460 | E34: -419 | F34: -553 | G34: -756 | I34: Leased assets obtained in exchange for new operating lease liabilities | K34: 758 | L34: 1027 | M34: 329 | N34: 580 | O34: 262
A35: Total shareholders' investment | C35: 14666 | D35: 13432 | E35: 11232 | F35: 12827 | G35: 14440
A36: Total liabilities and shareholders' investment | B36: $ | C36: 57769 | D36: 55356 | E36: 53335 | F36: 53811 | G36: 51248
A42: Dupont Model | B42: 2025 | C42: 2024 | D42: 2023 | E42: 2022 | F42: 2021
A43: PROFITABILITY | B43: =S14/S3 -> 0.038389355 | C43: =T14/T3 -> 0.03852456 | D43: =U14/U3 -> 0.02547654 | E43: =V14/V3 -> 0.065525211 | F43: =W14/W3 -> 0.046686119
A44: EFFICIENCY | B44: =S3/C20 -> 1.8446918 | C44: =T3/D20 -> 1.9403859 | D44: =U3/E20 -> 2.0459361 | E44: =V3/F20 -> 1.9699504 | F44: =W3/G20 -> 1.8256517
A45: LEVERAGE | B45: =C20/C35 -> 3.9389745 | C45: =D20/D35 -> 4.1212031 | D45: =E20/E35 -> 4.7484865 | E45: =F20/F35 -> 4.1951353 | F45: =G20/G35 -> 3.5490305
A46: RETURNS(ROE) | B46: =B43*B44*B45 -> 0.2789445 | C46: =C43*C44*C45 -> 0.30807028 | D46: =D43*D44*D45 -> 0.24750712 | E46: =E43*E44*E45 -> 0.54151399 | F46: =F43*F44*F45 -> 0.30249307

Sheet Traget-ratios
A1: Profitability | B1: 2025 | C1: 2024 | D1: 2023 | E1: 2022 | F1: 2021
A2: Gross Profit Margin= gross profit/ sales | B2: =('TARGET LTD, STATEMENTS & DuPont'!S3-'TARGET LTD, STATEMENTS & DuPont'!S4)/'TARGET LTD, STATEMENTS & DuPont'!S3 -> 0.28211625 | C2: =('TARGET LTD, STATEMENTS & DuPont'!T3-'TARGET LTD, STATEMENTS & DuPont'!T4)/'TARGET LTD, STATEMENTS & DuPont'!T3 -> 0.27542546 | D2: =('TARGET LTD, STATEMENTS & DuPont'!U3-'TARGET LTD, STATEMENTS & DuPont'!U4)/'TARGET LTD, STATEMENTS & DuPont'!U3 -> 0.24572947 | E2: =('TARGET LTD, STATEMENTS & DuPont'!V3-'TARGET LTD, STATEMENTS & DuPont'!V4)/'TARGET LTD, STATEMENTS & DuPont'!V3 -> 0.29283524 | F2: =('TARGET LTD, STATEMENTS & DuPont'!W3-'TARGET LTD, STATEMENTS & DuPont'!W4)/'TARGET LTD, STATEMENTS & DuPont'!W3 -> 0.29268606
A3: Operating Profit Margin = Operating profit/ sales | B3: ='TARGET LTD, STATEMENTS & DuPont'!S9/'TARGET LTD, STATEMENTS & DuPont'!S3 -> 0.052230543 | C3: ='TARGET LTD, STATEMENTS & DuPont'!T9/'TARGET LTD, STATEMENTS & DuPont'!T3 -> 0.053131866 | D3: ='TARGET LTD, STATEMENTS & DuPont'!U9/'TARGET LTD, STATEMENTS & DuPont'!U3 -> 0.03526393 | E3: ='TARGET LTD, STATEMENTS & DuPont'!V9/'TARGET LTD, STATEMENTS & DuPont'!V3 -> 0.084392246 | F3: ='TARGET LTD, STATEMENTS & DuPont'!W9/'TARGET LTD, STATEMENTS & DuPont'!W3 -> 0.069890232
A4: Net Profit Margin = net profit/ sales | B4: ='TARGET LTD, STATEMENTS & DuPont'!S14/'TARGET LTD, STATEMENTS & DuPont'!S3 -> 0.038389355 | C4: ='TARGET LTD, STATEMENTS & DuPont'!T14/'TARGET LTD, STATEMENTS & DuPont'!T3 -> 0.03852456 | D4: ='TARGET LTD, STATEMENTS & DuPont'!U14/'TARGET LTD, STATEMENTS & DuPont'!U3 -> 0.02547654 | E4: ='TARGET LTD, STATEMENTS & DuPont'!V14/'TARGET LTD, STATEMENTS & DuPont'!V3 -> 0.065525211 | F4: ='TARGET LTD, STATEMENTS & DuPont'!W14/'TARGET LTD, STATEMENTS & DuPont'!W3 -> 0.046686119
A6: Efficiency
A7: AR Days on Hand= (AR/Sales)*365 | B7: =('TARGET LTD, STATEMENTS & DuPont'!K11/'TARGET LTD, STATEMENTS & DuPont'!S3)*365 -> -1.0549331 | C7: =('TARGET LTD, STATEMENTS & DuPont'!L11/'TARGET LTD, STATEMENTS & DuPont'!T3)*365 -> -0.2888411 | D7: =('TARGET LTD, STATEMENTS & DuPont'!M11/'TARGET LTD, STATEMENTS & DuPont'!U3)*365 -> 0.07358871 | E7: =('TARGET LTD, STATEMENTS & DuPont'!N11/'TARGET LTD, STATEMENTS & DuPont'!V3)*365 -> -0.26857224 | F7: =('TARGET LTD, STATEMENTS & DuPont'!O11/'TARGET LTD, STATEMENTS & DuPont'!W3)*365 -> -0.53446415
A8: Inventory Days on Hand= (Inventory/COGS)*365 | B8: =('TARGET LTD, STATEMENTS & DuPont'!C4/'TARGET LTD, STATEMENTS & DuPont'!S4)*365 -> 60.784032 | C8: =('TARGET LTD, STATEMENTS & DuPont'!D4/'TARGET LTD, STATEMENTS & DuPont'!T4)*365 -> 55.743306 | D8: =('TARGET LTD, STATEMENTS & DuPont'!E4/'TARGET LTD, STATEMENTS & DuPont'!U4)*365 -> 59.863619 | E8: =('TARGET LTD, STATEMENTS & DuPont'!F4/'TARGET LTD, STATEMENTS & DuPont'!V4)*365 -> 67.689794 | F8: =('TARGET LTD, STATEMENTS & DuPont'!G4/'TARGET LTD, STATEMENTS & DuPont'!W4)*365 -> 58.756743
A9: AP Days on Hand= (AP*365)/COGS | B9: =('TARGET LTD, STATEMENTS & DuPont'!K12*365)/'TARGET LTD, STATEMENTS & DuPont'!S4 -> 4.809286 | C9: =('TARGET LTD, STATEMENTS & DuPont'!L12*365)/'TARGET LTD, STATEMENTS & DuPont'!T4 -> -5.7028319 | D9: =('TARGET LTD, STATEMENTS & DuPont'!M12*365)/'TARGET LTD, STATEMENTS & DuPont'!U4 -> -9.9203582 | E9: =('TARGET LTD, STATEMENTS & DuPont'!N12*365)/'TARGET LTD, STATEMENTS & DuPont'!V4 -> 12.795913 | F9: =('TARGET LTD, STATEMENTS & DuPont'!O12*365)/'TARGET LTD, STATEMENTS & DuPont'!W4 -> 16.132871
A10: Asset Turnover = Sales/ Total Assets | B10: ='TARGET LTD, STATEMENTS & DuPont'!S3/'TARGET LTD, STATEMENTS & DuPont'!C6 -> 5.4778452 | C10: ='TARGET LTD, STATEMENTS & DuPont'!T3/'TARGET LTD, STATEMENTS & DuPont'!D6 -> 6.1385301 | D10: ='TARGET LTD, STATEMENTS & DuPont'!U3/'TARGET LTD, STATEMENTS & DuPont'!E6 -> 6.1145355 | E10: ='TARGET LTD, STATEMENTS & DuPont'!V3/'TARGET LTD, STATEMENTS & DuPont'!F6 -> 4.9137811 | F10: ='TARGET LTD, STATEMENTS & DuPont'!W3/'TARGET LTD, STATEMENTS & DuPont'!G6 -> 4.5076604
A12: Leverage
A13: Debt/ Equity | B13: =('TARGET LTD, STATEMENTS & DuPont'!C21+'TARGET LTD, STATEMENTS & DuPont'!C25)/'TARGET LTD, STATEMENTS & DuPont'!C35 -> 1.8653348 | C13: =('TARGET LTD, STATEMENTS & DuPont'!D21+'TARGET LTD, STATEMENTS & DuPont'!D25)/'TARGET LTD, STATEMENTS & DuPont'!D35 -> 2.0116141 | D13: =('TARGET LTD, STATEMENTS & DuPont'!E21+'TARGET LTD, STATEMENTS & DuPont'!E25)/'TARGET LTD, STATEMENTS & DuPont'!E35 -> 2.6260684 | E13: =('TARGET LTD, STATEMENTS & DuPont'!F21+'TARGET LTD, STATEMENTS & DuPont'!F25)/'TARGET LTD, STATEMENTS & DuPont'!F35 -> 2.2629609 | F13: =('TARGET LTD, STATEMENTS & DuPont'!G21+'TARGET LTD, STATEMENTS & DuPont'!G25)/'TARGET LTD, STATEMENTS & DuPont'!G35 -> 1.6894044
A14: Liabilities/ Equity | B14: ='TARGET LTD, STATEMENTS & DuPont'!C30/'TARGET LTD, STATEMENTS & DuPont'!C35 -> 1.5207964 | C14: ='TARGET LTD, STATEMENTS & DuPont'!D30/'TARGET LTD, STATEMENTS & DuPont'!D35 -> 1.6840381 | D14: ='TARGET LTD, STATEMENTS & DuPont'!E30/'TARGET LTD, STATEMENTS & DuPont'!E35 -> 2.0123754 | E14: ='TARGET LTD, STATEMENTS & DuPont'!F30/'TARGET LTD, STATEMENTS & DuPont'!F35 -> 1.4997271 | F14: ='TARGET LTD, STATEMENTS & DuPont'!G30/'TARGET LTD, STATEMENTS & DuPont'!G35 -> 1.1553324
A15: LTD/ Total Captial = LTD/(STD+LTD+SE) | B15: ='TARGET LTD, STATEMENTS & DuPont'!C25/('TARGET LTD, STATEMENTS & DuPont'!C25+'TARGET LTD, STATEMENTS & DuPont'!C35+'TARGET LTD, STATEMENTS & DuPont'!C21) -> 0.34038503 | C15: ='TARGET LTD, STATEMENTS & DuPont'!D25/('TARGET LTD, STATEMENTS & DuPont'!D25+'TARGET LTD, STATEMENTS & DuPont'!D35+'TARGET LTD, STATEMENTS & DuPont'!D21) -> 0.36888164 | D15: ='TARGET LTD, STATEMENTS & DuPont'!E25/('TARGET LTD, STATEMENTS & DuPont'!E25+'TARGET LTD, STATEMENTS & DuPont'!E35+'TARGET LTD, STATEMENTS & DuPont'!E21) -> 0.39307111 | E15: ='TARGET LTD, STATEMENTS & DuPont'!F25/('TARGET LTD, STATEMENTS & DuPont'!F25+'TARGET LTD, STATEMENTS & DuPont'!F35+'TARGET LTD, STATEMENTS & DuPont'!F21) -> 0.32372055 | F15: ='TARGET LTD, STATEMENTS & DuPont'!G25/('TARGET LTD, STATEMENTS & DuPont'!G25+'TARGET LTD, STATEMENTS & DuPont'!G35+'TARGET LTD, STATEMENTS & DuPont'!G21) -> 0.29705163
A16: Debt/ EBITDA | B16: =('TARGET LTD, STATEMENTS & DuPont'!C21+'TARGET LTD, STATEMENTS & DuPont'!C25)/B32 -> 0.85912131 | C16: =('TARGET LTD, STATEMENTS & DuPont'!D21+'TARGET LTD, STATEMENTS & DuPont'!D25)/C32 -> 0.89707835 | D16: =('TARGET LTD, STATEMENTS & DuPont'!E21+'TARGET LTD, STATEMENTS & DuPont'!E25)/D32 -> 1.1139393 | E16: =('TARGET LTD, STATEMENTS & DuPont'!F21+'TARGET LTD, STATEMENTS & DuPont'!F25)/E32 -> 0.96489712 | F16: =('TARGET LTD, STATEMENTS & DuPont'!G21+'TARGET LTD, STATEMENTS & DuPont'!G25)/F32 -> 0.90968416
A17: Times Interest Earned | B17: ='TARGET LTD, STATEMENTS & DuPont'!S9/'TARGET LTD, STATEMENTS & DuPont'!S10 -> 13.542579 | C17: ='TARGET LTD, STATEMENTS & DuPont'!T9/'TARGET LTD, STATEMENTS & DuPont'!T10 -> 11.368526 | D17: ='TARGET LTD, STATEMENTS & DuPont'!U9/'TARGET LTD, STATEMENTS & DuPont'!U10 -> 8.0502092 | E17: ='TARGET LTD, STATEMENTS & DuPont'!V9/'TARGET LTD, STATEMENTS & DuPont'!V10 -> 21.249406 | F17: ='TARGET LTD, STATEMENTS & DuPont'!W9/'TARGET LTD, STATEMENTS & DuPont'!W10 -> 6.6929376
A18: FCCR= (EBITDA + Rent)/(Rent + Interest Expense) | B18: =B32/'TARGET LTD, STATEMENTS & DuPont'!S10 -> 77.476886 | C18: =C32/'TARGET LTD, STATEMENTS & DuPont'!T10 -> 60 | D18: =D32/'TARGET LTD, STATEMENTS & DuPont'!U10 -> 55.395397 | E18: =E32/'TARGET LTD, STATEMENTS & DuPont'!V10 -> 71.456057 | F18: =F32/'TARGET LTD, STATEMENTS & DuPont'!W10 -> 27.448311
A20: Liquidity
A21: Current Ratio= Current asset/ Current liabilities | B21: ='TARGET LTD, STATEMENTS & DuPont'!C6/'TARGET LTD, STATEMENTS & DuPont'!C24 -> 0.93533343 | C21: ='TARGET LTD, STATEMENTS & DuPont'!D6/'TARGET LTD, STATEMENTS & DuPont'!D24 -> 0.90644426 | D21: ='TARGET LTD, STATEMENTS & DuPont'!E6/'TARGET LTD, STATEMENTS & DuPont'!E24 -> 0.91517949 | E21: ='TARGET LTD, STATEMENTS & DuPont'!F6/'TARGET LTD, STATEMENTS & DuPont'!F24 -> 0.9919989 | F21: ='TARGET LTD, STATEMENTS & DuPont'!G6/'TARGET LTD, STATEMENTS & DuPont'!G24 -> 1.031354
A22: Quick Ratio= (Current assets-inventory)/Current Liabilities | B22: =('TARGET LTD, STATEMENTS & DuPont'!C6-'TARGET LTD, STATEMENTS & DuPont'!C4)/'TARGET LTD, STATEMENTS & DuPont'!C24 -> 0.32280398 | C22: =('TARGET LTD, STATEMENTS & DuPont'!D6-'TARGET LTD, STATEMENTS & DuPont'!D4)/'TARGET LTD, STATEMENTS & DuPont'!D24 -> 0.29071695 | D22: =('TARGET LTD, STATEMENTS & DuPont'!E6-'TARGET LTD, STATEMENTS & DuPont'!E4)/'TARGET LTD, STATEMENTS & DuPont'!E24 -> 0.22292308 | E22: =('TARGET LTD, STATEMENTS & DuPont'!F6-'TARGET LTD, STATEMENTS & DuPont'!F4)/'TARGET LTD, STATEMENTS & DuPont'!F24 -> 0.35273831 | F22: =('TARGET LTD, STATEMENTS & DuPont'!G6-'TARGET LTD, STATEMENTS & DuPont'!G4)/'TARGET LTD, STATEMENTS & DuPont'!G24 -> 0.50201242
A23: Cash Conversion Cycle= DSO+DIO-DPO | B23: =B7+B8+B9 -> 64.538385 | C23: =C7+C8+C9 -> 49.751633 | D23: =D7+D8+D9 -> 50.016849 | E23: =E7+E8+E9 -> 80.217134 | F23: =F7+F8+F9 -> 74.35515
A25: Returns
A26: ROE= NI/ SE | B26: ='TARGET LTD, STATEMENTS & DuPont'!S14/'TARGET LTD, STATEMENTS & DuPont'!C35 -> 0.2789445 | C26: ='TARGET LTD, STATEMENTS & DuPont'!T14/'TARGET LTD, STATEMENTS & DuPont'!D35 -> 0.30807028 | D26: ='TARGET LTD, STATEMENTS & DuPont'!U14/'TARGET LTD, STATEMENTS & DuPont'!E35 -> 0.24750712 | E26: ='TARGET LTD, STATEMENTS & DuPont'!V14/'TARGET LTD, STATEMENTS & DuPont'!F35 -> 0.54151399 | F26: ='TARGET LTD, STATEMENTS & DuPont'!W14/'TARGET LTD, STATEMENTS & DuPont'!G35 -> 0.30249307
A27: ROA= NI/ Total Assets | B27: ='TARGET LTD, STATEMENTS & DuPont'!S14/'TARGET LTD, STATEMENTS & DuPont'!C20 -> 0.070816528 | C27: ='TARGET LTD, STATEMENTS & DuPont'!T14/'TARGET LTD, STATEMENTS & DuPont'!D20 -> 0.074752511 | D27: ='TARGET LTD, STATEMENTS & DuPont'!U14/'TARGET LTD, STATEMENTS & DuPont'!E20 -> 0.052123371 | E27: ='TARGET LTD, STATEMENTS & DuPont'!V14/'TARGET LTD, STATEMENTS & DuPont'!F20 -> 0.12908141 | F27: ='TARGET LTD, STATEMENTS & DuPont'!W14/'TARGET LTD, STATEMENTS & DuPont'!G20 -> 0.085232594
A28: ROC= NOPAT/ Captial | B28: =B33/('TARGET LTD, STATEMENTS & DuPont'!C25+'TARGET LTD, STATEMENTS & DuPont'!C35) -> 0.14940182 | C28: =C33/('TARGET LTD, STATEMENTS & DuPont'!D25+'TARGET LTD, STATEMENTS & DuPont'!D35) -> 0.15723675 | D28: =D33/('TARGET LTD, STATEMENTS & DuPont'!E25+'TARGET LTD, STATEMENTS & DuPont'!E35) -> 0.11489067 | E28: =E33/('TARGET LTD, STATEMENTS & DuPont'!F25+'TARGET LTD, STATEMENTS & DuPont'!F35) -> 0.26449854 | F28: =F33/('TARGET LTD, STATEMENTS & DuPont'!G25+'TARGET LTD, STATEMENTS & DuPont'!G35) -> 0.19826307
B29: 2025 | C29: 2024 | D29: 2023 | E29: 2022 | F29: 2021
A30: Net Income | B30: ='TARGET LTD, STATEMENTS & DuPont'!S14 -> 4091 | C30: ='TARGET LTD, STATEMENTS & DuPont'!T14 -> 4138 | D30: ='TARGET LTD, STATEMENTS & DuPont'!U14 -> 2780 | E30: ='TARGET LTD, STATEMENTS & DuPont'!V14 -> 6946 | F30: ='TARGET LTD, STATEMENTS & DuPont'!W14 -> 4368
A31: EBIT | B31: ='TARGET LTD, STATEMENTS & DuPont'!S9 -> 5566 | C31: ='TARGET LTD, STATEMENTS & DuPont'!T9 -> 5707 | D31: ='TARGET LTD, STATEMENTS & DuPont'!U9 -> 3848 | E31: ='TARGET LTD, STATEMENTS & DuPont'!V9 -> 8946 | F31: ='TARGET LTD, STATEMENTS & DuPont'!W9 -> 6539
A32: EBITDA | B32: ='TARGET LTD, STATEMENTS & DuPont'!S9-'TARGET LTD, STATEMENTS & DuPont'!C14 -> 31843 | C32: ='TARGET LTD, STATEMENTS & DuPont'!T9-'TARGET LTD, STATEMENTS & DuPont'!D14 -> 30120 | D32: ='TARGET LTD, STATEMENTS & DuPont'!U9-'TARGET LTD, STATEMENTS & DuPont'!E14 -> 26479 | E32: ='TARGET LTD, STATEMENTS & DuPont'!V9-'TARGET LTD, STATEMENTS & DuPont'!F14 -> 30083 | F32: ='TARGET LTD, STATEMENTS & DuPont'!W9-'TARGET LTD, STATEMENTS & DuPont'!G14 -> 26817
A33: NOPAT | B33: ='TARGET LTD, STATEMENTS & DuPont'!S9*(1-B34) -> 4328.1707 | C33: ='TARGET LTD, STATEMENTS & DuPont'!T9*(1-C34) -> 4458.2907 | D33: ='TARGET LTD, STATEMENTS & DuPont'!U9*(1-D34) -> 3129.7367 | E33: ='TARGET LTD, STATEMENTS & DuPont'!V9*(1-E34) -> 6976.4136 | F33: ='TARGET LTD, STATEMENTS & DuPont'!W9*(1-F34) -> 5150.0815
A34: Tax rate | B34: ='TARGET LTD, STATEMENTS & DuPont'!S13/'TARGET LTD, STATEMENTS & DuPont'!S12 -> 0.22239118 | C34: ='TARGET LTD, STATEMENTS & DuPont'!T13/'TARGET LTD, STATEMENTS & DuPont'!T12 -> 0.2188031 | D34: ='TARGET LTD, STATEMENTS & DuPont'!U13/'TARGET LTD, STATEMENTS & DuPont'!U12 -> 0.18665886 | E34: ='TARGET LTD, STATEMENTS & DuPont'!V13/'TARGET LTD, STATEMENTS & DuPont'!V12 -> 0.22016392 | F34: ='TARGET LTD, STATEMENTS & DuPont'!W13/'TARGET LTD, STATEMENTS & DuPont'!W12 -> 0.21240534
A35: CFFO | B35: ='TARGET LTD, STATEMENTS & DuPont'!S14+'TARGET LTD, STATEMENTS & DuPont'!S6+('TARGET LTD, STATEMENTS & DuPont'!C4-'TARGET LTD, STATEMENTS & DuPont'!D4)+('TARGET LTD, STATEMENTS & DuPont'!K12-'TARGET LTD, STATEMENTS & DuPont'!L12)+'TARGET LTD, STATEMENTS & DuPont'!S13 -> 10868 | C35: ='TARGET LTD, STATEMENTS & DuPont'!T14+'TARGET LTD, STATEMENTS & DuPont'!T6+('TARGET LTD, STATEMENTS & DuPont'!D4-'TARGET LTD, STATEMENTS & DuPont'!E4)+('TARGET LTD, STATEMENTS & DuPont'!L12-'TARGET LTD, STATEMENTS & DuPont'!M12)+'TARGET LTD, STATEMENTS & DuPont'!T13 -> 7120 | D35: ='TARGET LTD, STATEMENTS & DuPont'!U14+'TARGET LTD, STATEMENTS & DuPont'!U6+('TARGET LTD, STATEMENTS & DuPont'!E4-'TARGET LTD, STATEMENTS & DuPont'!F4)+('TARGET LTD, STATEMENTS & DuPont'!M12-'TARGET LTD, STATEMENTS & DuPont'!N12)+'TARGET LTD, STATEMENTS & DuPont'!U13 -> 535 | E35: ='TARGET LTD, STATEMENTS & DuPont'!V14+'TARGET LTD, STATEMENTS & DuPont'!V6+('TARGET LTD, STATEMENTS & DuPont'!F4-'TARGET LTD, STATEMENTS & DuPont'!G4)+('TARGET LTD, STATEMENTS & DuPont'!N12-'TARGET LTD, STATEMENTS & DuPont'!O12)+'TARGET LTD, STATEMENTS & DuPont'!V13 -> 14203 | F35: ='TARGET LTD, STATEMENTS & DuPont'!W14+'TARGET LTD, STATEMENTS & DuPont'!W6+('TARGET LTD, STATEMENTS & DuPont'!G4-'TARGET LTD, STATEMENTS & DuPont'!H4)+('TARGET LTD, STATEMENTS & DuPont'!O12-'TARGET LTD, STATEMENTS & DuPont'!P12)+'TARGET LTD, STATEMENTS & DuPont'!W13 -> 21354
A36: FCF | B36: =(B35+'TARGET LTD, STATEMENTS & DuPont'!K15)-'TARGET LTD, STATEMENTS & DuPont'!S10 -> 7566 | C36: =(C35+'TARGET LTD, STATEMENTS & DuPont'!L15)-'TARGET LTD, STATEMENTS & DuPont'!T10 -> 1812 | D36: =(D35+'TARGET LTD, STATEMENTS & DuPont'!M15)-'TARGET LTD, STATEMENTS & DuPont'!U10 -> -5471 | E36: =(E35+'TARGET LTD, STATEMENTS & DuPont'!N15)-'TARGET LTD, STATEMENTS & DuPont'!V10 -> 17326 | F36: =(F35+'TARGET LTD, STATEMENTS & DuPont'!O15)-'TARGET LTD, STATEMENTS & DuPont'!W10 -> 17728
A38: Market Metrics
A39: EPS = NI/ Share Outstanding | B39: ='TARGET LTD, STATEMENTS & DuPont'!S14/'TARGET LTD, STATEMENTS & DuPont'!S18 -> 8.8857515 | C39: ='TARGET LTD, STATEMENTS & DuPont'!T14/'TARGET LTD, STATEMENTS & DuPont'!T18 -> 8.9664139 | D39: ='TARGET LTD, STATEMENTS & DuPont'!U14/'TARGET LTD, STATEMENTS & DuPont'!U18 -> 6.0160138 | E39: ='TARGET LTD, STATEMENTS & DuPont'!V14/'TARGET LTD, STATEMENTS & DuPont'!V18 -> 14.23069 | F39: ='TARGET LTD, STATEMENTS & DuPont'!W14/'TARGET LTD, STATEMENTS & DuPont'!W18 -> 8.7255294
A40: PE= Price-to-Earnings | B40: =I41/'TARGET LTD, STATEMENTS & DuPont'!S14 -> 0.022811049 | C40: =I44/'TARGET LTD, STATEMENTS & DuPont'!T14 -> 0.032636539 | D40: =I46/'TARGET LTD, STATEMENTS & DuPont'!U14 -> 0.051230216 | E40: =I48/'TARGET LTD, STATEMENTS & DuPont'!V14 -> 0.021456954 | F40: =I50/'TARGET LTD, STATEMENTS & DuPont'!W14 -> 0.053092949 | H40: {=_xlfn.STOCKHISTORY("TGT",TODAY()-1,TODAY(),0,1)} -> Date | I40: Close
A41: PB= Price-to-Book | B41: ='Traget-ratios'!I41/('TARGET LTD, STATEMENTS & DuPont'!C35/'TARGET LTD, STATEMENTS & DuPont'!S18) -> 2.9295328 | C41: ='Traget-ratios'!I44/('TARGET LTD, STATEMENTS & DuPont'!D35/'TARGET LTD, STATEMENTS & DuPont'!T18) -> 4.6400815 | D41: ='Traget-ratios'!I46/('TARGET LTD, STATEMENTS & DuPont'!E35/'TARGET LTD, STATEMENTS & DuPont'!U18) -> 5.8593556 | E41: ='Traget-ratios'!I48/('TARGET LTD, STATEMENTS & DuPont'!F35/'TARGET LTD, STATEMENTS & DuPont'!V18) -> 5.6713514 | F41: ='Traget-ratios'!I50/('TARGET LTD, STATEMENTS & DuPont'!G35/'TARGET LTD, STATEMENTS & DuPont'!W18) -> 8.0397608 | H41: 45810 | I41: 93.32
A42: Dividend Yield | B42: =1.12/I41 -> 0.012001715 | C42: =4.44/I44 -> 0.032876712 | D42: =4.36/I46 -> 0.030613678 | E42: =3.96/I48 -> 0.026570048 | F42: =3.16/I50 -> 0.013625976 | H42: 45811 | I42: 95.78
A43: Market Capitalization | B43: =I41*'TARGET LTD, STATEMENTS & DuPont'!S18 -> 42964.528 | C43: =I44*'TARGET LTD, STATEMENTS & DuPont'!T18 -> 62325.575 | D43: =I46*'TARGET LTD, STATEMENTS & DuPont'!U18 -> 65812.282 | E43: =I48*'TARGET LTD, STATEMENTS & DuPont'!V18 -> 72746.424 | F43: =I50*'TARGET LTD, STATEMENTS & DuPont'!W18 -> 116094.15 | H43: {=_xlfn.STOCKHISTORY("TGT",DATE(2024,12,30),DATE(2024,12,30),0,1)} -> Date | I43: Close
A44: EV/EBITDA | B44: =((B43+'TARGET LTD, STATEMENTS & DuPont'!C25+'TARGET LTD, STATEMENTS & DuPont'!C28)-'TARGET LTD, STATEMENTS & DuPont'!C3)/('TARGET LTD, STATEMENTS & DuPont'!S9+'TARGET LTD, STATEMENTS & DuPont'!S6) -> 6.7475637 | C44: =((C43+'TARGET LTD, STATEMENTS & DuPont'!D25+'TARGET LTD, STATEMENTS & DuPont'!D28)-'TARGET LTD, STATEMENTS & DuPont'!D3)/('TARGET LTD, STATEMENTS & DuPont'!T9+'TARGET LTD, STATEMENTS & DuPont'!T6) -> 9.2811592 | D44: =((D43+'TARGET LTD, STATEMENTS & DuPont'!E25+'TARGET LTD, STATEMENTS & DuPont'!E28)-'TARGET LTD, STATEMENTS & DuPont'!E3)/('TARGET LTD, STATEMENTS & DuPont'!U9+'TARGET LTD, STATEMENTS & DuPont'!U6) -> 13.051866 | E44: =((E43+'TARGET LTD, STATEMENTS & DuPont'!F25+'TARGET LTD, STATEMENTS & DuPont'!F28)-'TARGET LTD, STATEMENTS & DuPont'!F3)/('TARGET LTD, STATEMENTS & DuPont'!V9+'TARGET LTD, STATEMENTS & DuPont'!V6) -> 7.2642537 | F44: =((F43+'TARGET LTD, STATEMENTS & DuPont'!G25+'TARGET LTD, STATEMENTS & DuPont'!G28)-'TARGET LTD, STATEMENTS & DuPont'!G3)/('TARGET LTD, STATEMENTS & DuPont'!W9+'TARGET LTD, STATEMENTS & DuPont'!W6) -> 13.80524 | H44: 45656 | I44: 135.05
H45: {=_xlfn.STOCKHISTORY("TGT",DATE(2023,12,29),DATE(2023,12,29),0,1)} -> Date | I45: Close
...

Sheet Sheet5
